Workbook

Sheet Dashboard Ready
A1: # | B1: Code | C1: Name | D1: Description | E1: Industry | F1: Last Period | G1: Base Period | H1: PER | I1: PBV | J1: PEG | K1: NPM | L1: Sheet Link (LibreOffice Calc) | M1: Sheet Link (Microsoft Excel) | O1: Copy & Filter | AD1: /
A2: 1 | B2: AAAA | E2: =IFERROR(INDIRECT("'" & $B2 & "'!B1"), "") | F2: =IFERROR(INDIRECT("'" & $B2 & "'!C2"), "") | G2: =IFERROR(INDIRECT("'" & $B2 & "'!" & ADDRESS(2, COUNTA(INDIRECT("'" & $B2 & "'!2:2")))), "") | H2: =IFERROR(INDIRECT("'" & $B2 & "'!C35"), "") | I2: =IFERROR(INDIRECT("'" & $B2 & "'!C36"), "") | J2: =IFERROR(INDIRECT("'" & $B2 & "'!C37"), "") | K2: =IFERROR(INDIRECT("'" & $B2 & "'!C40"), "") | L2: =HYPERLINK("#" & $B2 & ".A1", $B2 & " Worksheet") -> AAAA Worksheet | M2: =HYPERLINK("#'" & $B2 & "'!A1", $B2 & " Worksheet") -> AAAA Worksheet
A3: =A2+1 -> 2 | B3: BBBB | E3: =IFERROR(INDIRECT("'" & $B3 & "'!B1"), "") | F3: =IFERROR(INDIRECT("'" & $B3 & "'!C2"), "") | G3: =IFERROR(INDIRECT("'" & $B3 & "'!" & ADDRESS(2, COUNTA(INDIRECT("'" & $B3 & "'!2:2")))), "") | H3: =IFERROR(INDIRECT("'" & $B3 & "'!C35"), "") | I3: =IFERROR(INDIRECT("'" & $B3 & "'!C36"), "") | J3: =IFERROR(INDIRECT("'" & $B3 & "'!C37"), "") | K3: =IFERROR(INDIRECT("'" & $B3 & "'!C40"), "") | L3: =HYPERLINK("#" & $B3 & ".A1", $B3 & " Worksheet") -> BBBB Worksheet | M3: =HYPERLINK("#'" & $B3 & "'!A1", $B3 & " Worksheet") -> BBBB Worksheet

Sheet Divider 1

Sheet Q&YTD Ready - Quartely Report
A1: AAAA | B1: Integrated Freight & Logistics | C1: {=IF(C$7="Local Currency",1,_xlfn.XLOOKUP(C$2,OFFSET(Dashboard!$A:$A,0,MATCH(C$7,Dashboard!$1:$1,0)-1),OFFSET(Dashboard!$A:$A,0,MATCH(C$7,Dashboard!$1:$1,0))))} -> 1 | D1: {=IF(D$7="Local Currency",1,_xlfn.XLOOKUP(D$2,OFFSET(Dashboard!$A:$A,0,MATCH(D$7,Dashboard!$1:$1,0)-1),OFFSET(Dashboard!$A:$A,0,MATCH(D$7,Dashboard!$1:$1,0))))} -> 1 | E1: {=IF(E$7="Local Currency",1,_xlfn.XLOOKUP(E$2,OFFSET(Dashboard!$A:$A,0,MATCH(E$7,Dashboard!$1:$1,0)-1),OFFSET(Dashboard!$A:$A,0,MATCH(E$7,Dashboard!$1:$1,0))))} -> 1 | F1: {=IF(F$7="Local Currency",1,_xlfn.XLOOKUP(F$2,OFFSET(Dashboard!$A:$A,0,MATCH(F$7,Dashboard!$1:$1,0)-1),OFFSET(Dashboard!$A:$A,0,MATCH(F$7,Dashboard!$1:$1,0))))} -> 1 | G1: {=IF(G$7="Local Currency",1,_xlfn.XLOOKUP(G$2,OFFSET(Dashboard!$A:$A,0,MATCH(G$7,Dashboard!$1:$1,0)-1),OFFSET(Dashboard!$A:$A,0,MATCH(G$7,Dashboard!$1:$1,0))))} -> 1 | H1: {=IF(H$7="Local Currency",1,_xlfn.XLOOKUP(H$2,OFFSET(Dashboard!$A:$A,0,MATCH(H$7,Dashboard!$1:$1,0)-1),OFFSET(Dashboard!$A:$A,0,MATCH(H$7,Dashboard!$1:$1,0))))} -> 1 | I1: {=IF(I$7="Local Currency",1,_xlfn.XLOOKUP(I$2,OFFSET(Dashboard!$A:$A,0,MATCH(I$7,Dashboard!$1:$1,0)-1),OFFSET(Dashboard!$A:$A,0,MATCH(I$7,Dashboard!$1:$1,0))))} -> 1 | J1: {=IF(J$7="Local Currency",1,_xlfn.XLOOKUP(J$2,OFFSET(Dashboard!$A:$A,0,MATCH(J$7,Dashboard!$1:$1,0)-1),OFFSET(Dashboard!$A:$A,0,MATCH(J$7,Dashboard!$1:$1,0))))} -> 1 | ... V1: {=IF(V$7="Local Currency",1,_xlfn.XLOOKUP(V$2,OFFSET(Dashboard!$A:$A,0,MATCH(V$7,Dashboard!$1:$1,0)-1),OFFSET(Dashboard!$A:$A,0,MATCH(V$7,Dashboard!$1:$1,0))))} -> 1
A2: Market Data | B2: Current | C2: FY2025 | D2: 9M2025 | E2: 1H2025 | F2: 1Q2025 | G2: FY2024 | H2: 9M2024 | I2: 1H2024 | J2: 1Q2024 | K2: FY2023 | L2: 9M2023 | M2: 1H2023 | N2: 1Q2023 | O2: FY2022 | P2: 9M2022 | Q2: 1H2022 | R2: 1Q2022 | S2: FY2021 | T2: 9M2021 | U2: 1H2021 | V2: 1Q2021
A3: Price | B3: 1335 | C3: 1385 | D3: 1065 | E3: 1010 | F3: 775 | G3: 705 | H3: 685 | I3: 670 | J3: 690 | K3: 715 | L3: 710 | M3: 765 | N3: 625 | O3: 570 | P3: 505 | Q3: 615 | R3: 550 | S3: 515 | T3: 595 | U3: 490 | V3: 595
A5: Market Capitalization | B5: =B$3*OFFSET(B$5,0,1)/OFFSET(B$3,0,1) -> 2427178984665 | C5: =C$23*C$3 -> 2518084564615 | D5: =D$23*D$3 -> 1936684063785 | E5: =E$23*E$3 -> 1836493590860 | F5: =F$23*F$3 -> 1409291726950 | G5: =G$23*G$3 -> 1281580755315 | H5: =H$23*H$3 -> 1245773686145 | I5: =I$23*I$3 -> 1218278165400 | J5: =J$23*J$3 -> 1254740877600 | ... V5: =V$23*V$3 -> 1082036929295
A7: Currency | B7: {=IF(COUNTIF($C7:$7,INDEX($C7:$7,MATCH(TRUE,$C7:$7<>"",0)))=COUNTIF($C7:$7,"<>"),"All "&INDEX($C7:$7,MATCH(TRUE,$C7:$7<>"",0)),INDEX($C7:$7,MATCH(MAX(INDEX(COUNTIF($C7:$7,$C7:$7),0)),INDEX(COUNTIF($C7:$7,$C7:$7),0),0))&" Dominant")} -> All Local Currency | C7: Local Currency | D7: Local Currency | E7: Local Currency | F7: Local Currency | G7: Local Currency | H7: Local Currency | I7: Local Currency | J7: Local Currency | K7: Local Currency | L7: Local Currency | M7: Local Currency | N7: Local Currency | O7: Local Currency | P7: Local Currency | Q7: Local Currency | R7: Local Currency | S7: Local Currency | T7: Local Currency | U7: Local Currency | V7: Local Currency
A9: Consolidated Statements of Income | B9: =B$2 -> Current | C9: =C$2 -> FY2025 | D9: =D$2 -> 9M2025 | E9: =E$2 -> 1H2025 | F9: =F$2 -> 1Q2025 | G9: =G$2 -> FY2024 | H9: =H$2 -> 9M2024 | I9: =I$2 -> 1H2024 | ... V9: =V$2 -> 1Q2021
A10: Period Type | B10: {=IF(COUNTIF($C10:$10,INDEX($C10:$10,MATCH(TRUE,$C10:$10<>"",0)))=COUNTIF($C10:$10,"<>"),"All "&INDEX($C10:$10,MATCH(TRUE,$C10:$10<>"",0)),INDEX($C10:$10,MATCH(MAX(INDEX(COUNTIF($C10:$10,$C10:$10),0)),INDEX(COUNTIF($C10:$10,$C10:$10),0),0))&" Dominant")} -> All Quarterly | C10: Quarterly | D10: Quarterly | E10: Quarterly | F10: Quarterly | G10: Quarterly | H10: Quarterly | I10: Quarterly | J10: Quarterly | K10: Quarterly | L10: Quarterly | M10: Quarterly | N10: Quarterly | O10: Quarterly | P10: Quarterly | Q10: Quarterly | R10: Quarterly | S10: Quarterly | T10: Quarterly | U10: Quarterly | V10: Quarterly
A12: Revenue | C12: 269720224000 | D12: 244690118000 | E12: 212278201000 | F12: 203271873000 | G12: 238772010000 | H12: 225562144000 | I12: 184623863000 | J12: 175637819000 | K12: 187042816000 | L12: 181201900000 | M12: 175808477000 | N12: 191151747000 | O12: 218233269000 | P12: 206003408000 | Q12: 152290456000 | R12: 150046126000 | S12: 169064709000 | T12: 114487473000 | U12: 113360881000 | V12: 119923887000
A13: Net Income | C13: 66215970000 | D13: 76450065000 | E13: 62675757000 | F13: 51170928000 | G13: 64191999000 | H13: 67336572000 | I13: 42299859000 | J13: 38387797000 | K13: 48911907000 | L13: 63025448000 | M13: 36583493000 | N13: 42333996000 | O13: 52829242000 | P13: 63479716000 | Q13: 10151585000 | R13: 35264224000 | S13: 43459819000 | T13: 1763922000 | U13: -3058854000 | V13: 17891287000
A15: Revenue (Quarterly) | C15: =IF(C$10="Quarterly",C$12,IF(LEFT(C$2,2)="1Q",C$16,C$16-D$16)) -> 269720224000 | D15: =IF(D$10="Quarterly",D$12,IF(LEFT(D$2,2)="1Q",D$16,D$16-E$16)) -> 244690118000 | E15: =IF(E$10="Quarterly",E$12,IF(LEFT(E$2,2)="1Q",E$16,E$16-F$16)) -> 212278201000 | F15: =IF(F$10="Quarterly",F$12,IF(LEFT(F$2,2)="1Q",F$16,F$16-G$16)) -> 203271873000 | G15: =IF(G$10="Quarterly",G$12,IF(LEFT(G$2,2)="1Q",G$16,G$16-H$16)) -> 238772010000 | H15: =IF(H$10="Quarterly",H$12,IF(LEFT(H$2,2)="1Q",H$16,H$16-I$16)) -> 225562144000 | I15: =IF(I$10="Quarterly",I$12,IF(LEFT(I$2,2)="1Q",I$16,I$16-J$16)) -> 184623863000 | J15: =IF(J$10="Quarterly",J$12,IF(LEFT(J$2,2)="1Q",J$16,J$16-K$16)) -> 175637819000 | ... V15: =IF(V$10="Quarterly",V$12,IF(LEFT(V$2,2)="1Q",V$16,V$16-W$16)) -> 119923887000
A16: Revenue (YTD) | C16: =IF(C$10="YTD",C$12,IF(LEFT(C$2,2)="1Q",C$15,IF(LEFT(C$2,2)="1H",SUM(C$15:D$15),IF(LEFT(C$2,2)="9M",SUM(C$15:E$15),SUM(C$15:F$15))))) -> 929960416000 | D16: =IF(D$10="YTD",D$12,IF(LEFT(D$2,2)="1Q",D$15,IF(LEFT(D$2,2)="1H",SUM(D$15:E$15),IF(LEFT(D$2,2)="9M",SUM(D$15:F$15),SUM(D$15:G$15))))) -> 660240192000 | E16: =IF(E$10="YTD",E$12,IF(LEFT(E$2,2)="1Q",E$15,IF(LEFT(E$2,2)="1H",SUM(E$15:F$15),IF(LEFT(E$2,2)="9M",SUM(E$15:G$15),SUM(E$15:H$15))))) -> 415550074000 | F16: =IF(F$10="YTD",F$12,IF(LEFT(F$2,2)="1Q",F$15,IF(LEFT(F$2,2)="1H",SUM(F$15:G$15),IF(LEFT(F$2,2)="9M",SUM(F$15:H$15),SUM(F$15:I$15))))) -> 203271873000 | G16: =IF(G$10="YTD",G$12,IF(LEFT(G$2,2)="1Q",G$15,IF(LEFT(G$2,2)="1H",SUM(G$15:H$15),IF(LEFT(G$2,2)="9M",SUM(G$15:I$15),SUM(G$15:J$15))))) -> 824595836000 | H16: =IF(H$10="YTD",H$12,IF(LEFT(H$2,2)="1Q",H$15,IF(LEFT(H$2,2)="1H",SUM(H$15:I$15),IF(LEFT(H$2,2)="9M",SUM(H$15:J$15),SUM(H$15:K$15))))) -> 585823826000 | I16: =IF(I$10="YTD",I$12,IF(LEFT(I$2,2)="1Q",I$15,IF(LEFT(I$2,2)="1H",SUM(I$15:J$15),IF(LEFT(I$2,2)="9M",SUM(I$15:K$15),SUM(I$15:L$15))))) -> 360261682000 | J16: =IF(J$10="YTD",J$12,IF(LEFT(J$2,2)="1Q",J$15,IF(LEFT(J$2,2)="1H",SUM(J$15:K$15),IF(LEFT(J$2,2)="9M",SUM(J$15:L$15),SUM(J$15:M$15))))) -> 175637819000 | ... V16: =IF(V$10="YTD",V$12,IF(LEFT(V$2,2)="1Q",V$15,IF(LEFT(V$2,2)="1H",SUM(V$15:W$15),IF(LEFT(V$2,2)="9M",SUM(V$15:X$15),SUM(V$15:Y$15))))) -> 119923887000
A17: Revenue Growth (YoY) | C17: =(C$16-G$16)/ABS(G$16) -> 0.12777724 | D17: =(D$16-H$16)/ABS(H$16) -> 0.12702858 | E17: =(E$16-I$16)/ABS(I$16) -> 0.15346731 | F17: =(F$16-J$16)/ABS(J$16) -> 0.15733544 | G17: =(G$16-K$16)/ABS(K$16) -> 0.12158636 | H17: =(H$16-L$16)/ABS(L$16) -> 0.068705407 | I17: =(I$16-M$16)/ABS(M$16) -> -0.018254136 | J17: =(J$16-N$16)/ABS(N$16) -> -0.081160273 | ... V17: =(V$16-Z$16)/ABS(Z$16) -> #DIV/0!
A19: Net Income (Quarterly) | C19: =IF(C$10="Quarterly",C$13,IF(LEFT(C$2,2)="1Q",C$20,C$20-D$20)) -> 66215970000 | D19: =IF(D$10="Quarterly",D$13,IF(LEFT(D$2,2)="1Q",D$20,D$20-E$20)) -> 76450065000 | E19: =IF(E$10="Quarterly",E$13,IF(LEFT(E$2,2)="1Q",E$20,E$20-F$20)) -> 62675757000 | F19: =IF(F$10="Quarterly",F$13,IF(LEFT(F$2,2)="1Q",F$20,F$20-G$20)) -> 51170928000 | G19: =IF(G$10="Quarterly",G$13,IF(LEFT(G$2,2)="1Q",G$20,G$20-H$20)) -> 64191999000 | H19: =IF(H$10="Quarterly",H$13,IF(LEFT(H$2,2)="1Q",H$20,H$20-I$20)) -> 67336572000 | I19: =IF(I$10="Quarterly",I$13,IF(LEFT(I$2,2)="1Q",I$20,I$20-J$20)) -> 42299859000 | J19: =IF(J$10="Quarterly",J$13,IF(LEFT(J$2,2)="1Q",J$20,J$20-K$20)) -> 38387797000 | ... V19: =IF(V$10="Quarterly",V$13,IF(LEFT(V$2,2)="1Q",V$20,V$20-W$20)) -> 17891287000
A20: Net Income (YTD) | C20: =IF(C$10="YTD",C$13,IF(LEFT(C$2,2)="1Q",C$19,IF(LEFT(C$2,2)="1H",SUM(C$19:D$19),IF(LEFT(C$2,2)="9M",SUM(C$19:E$19),SUM(C$19:F$19))))) -> 256512720000 | D20: =IF(D$10="YTD",D$13,IF(LEFT(D$2,2)="1Q",D$19,IF(LEFT(D$2,2)="1H",SUM(D$19:E$19),IF(LEFT(D$2,2)="9M",SUM(D$19:F$19),SUM(D$19:G$19))))) -> 190296750000 | E20: =IF(E$10="YTD",E$13,IF(LEFT(E$2,2)="1Q",E$19,IF(LEFT(E$2,2)="1H",SUM(E$19:F$19),IF(LEFT(E$2,2)="9M",SUM(E$19:G$19),SUM(E$19:H$19))))) -> 113846685000 | F20: =IF(F$10="YTD",F$13,IF(LEFT(F$2,2)="1Q",F$19,IF(LEFT(F$2,2)="1H",SUM(F$19:G$19),IF(LEFT(F$2,2)="9M",SUM(F$19:H$19),SUM(F$19:I$19))))) -> 51170928000 | G20: =IF(G$10="YTD",G$13,IF(LEFT(G$2,2)="1Q",G$19,IF(LEFT(G$2,2)="1H",SUM(G$19:H$19),IF(LEFT(G$2,2)="9M",SUM(G$19:I$19),SUM(G$19:J$19))))) -> 212216227000 | H20: =IF(H$10="YTD",H$13,IF(LEFT(H$2,2)="1Q",H$19,IF(LEFT(H$2,2)="1H",SUM(H$19:I$19),IF(LEFT(H$2,2)="9M",SUM(H$19:J$19),SUM(H$19:K$19))))) -> 148024228000 | I20: =IF(I$10="YTD",I$13,IF(LEFT(I$2,2)="1Q",I$19,IF(LEFT(I$2,2)="1H",SUM(I$19:J$19),IF(LEFT(I$2,2)="9M",SUM(I$19:K$19),SUM(I$19:L$19))))) -> 80687656000 | J20: =IF(J$10="YTD",J$13,IF(LEFT(J$2,2)="1Q",J$19,IF(LEFT(J$2,2)="1H",SUM(J$19:K$19),IF(LEFT(J$2,2)="9M",SUM(J$19:L$19),SUM(J$19:M$19))))) -> 38387797000 | ... V20: =IF(V$10="YTD",V$13,IF(LEFT(V$2,2)="1Q",V$19,IF(LEFT(V$2,2)="1H",SUM(V$19:W$19),IF(LEFT(V$2,2)="9M",SUM(V$19:X$19),SUM(V$19:Y$19))))) -> 17891287000
A21: Net Income Growth (YoY) | C21: =(C$20-G$20)/ABS(G$20) -> 0.20873283 | D21: =(D$20-H$20)/ABS(H$20) -> 0.2855784 | E21: =(E$20-I$20)/ABS(I$20) -> 0.41095541 | F21: =(F$20-J$20)/ABS(J$20) -> 0.33299986 | G21: =(G$20-K$20)/ABS(K$20) -> 0.11192476 | H21: =(H$20-L$20)/ABS(L$20) -> 0.04284321 | I21: =(I$20-M$20)/ABS(M$20) -> 0.022430605 | J21: =(J$20-N$20)/ABS(N$20) -> -0.09321584 | ... V21: =(V$20-Z$20)/ABS(Z$20) -> #DIV/0!
A23: Shares Outstanding | C23: 1818111599 | D23: 1818482689 | E23: 1818310486 | F23: 1818440938 | G23: 1817845043 | H23: 1818647717 | I23: 1818325620 | J23: 1818465040 | K23: 1818284091 | L23: 1818396817 | M23: 1818280026 | N23: 1818470618 | O23: 1818277789 | P23: 1818384807 | Q23: 1818088723 | R23: 1818680969 | S23: 1819576943 | T23: 1816577843 | U23: 1818549461 | V23: 1818549461
A25: Consolidated Balance Sheets | B25: =B$2 -> Current | C25: =C$2 -> FY2025 | D25: =D$2 -> 9M2025 | E25: =E$2 -> 1H2025 | F25: =F$2 -> 1Q2025 | G25: =G$2 -> FY2024 | H25: =H$2 -> 9M2024 | I25: =I$2 -> 1H2024 | ... V25: =V$2 -> 1Q2021
A26: Shareholders' Equity | C26: 1360801231000 | D26: 1342159480000 | E26: 1265709415000 | F26: 1328399319000 | G26: 1277228391000 | H26: 1257666157000 | I26: 1190106935000 | J26: 1261254651000 | K26: 1222866854000 | L26: 1213408389000 | M26: 1240883954000 | N26: 1204304183000 | O26: 1161970187000 | P26: 1131848849000 | Q26: 1110408454000 | R26: 1100256869000 | S26: 1064992645000 | T26: 1021532826000 | U26: 1019768905000 | V26: 1022827759000
A28: Ratio Analysis | B28: =B$2 -> Current | C28: =C$2 -> FY2025 | D28: =D$2 -> 9M2025 | E28: =E$2 -> 1H2025 | F28: =F$2 -> 1Q2025 | G28: =G$2 -> FY2024 | H28: =H$2 -> 9M2024 | I28: =I$2 -> 1H2024 | ... V28: =V$2 -> 1Q2021
A29: Earnings
A30: Earnings Per Share (EPS) (Quarterly) | C30: =C$19*C$1/C$23 -> 36.42019 | D30: =D$19*D$1/D$23 -> 42.040579 | E30: =E$19*E$1/E$23 -> 34.469227 | F30: =F$19*F$1/F$23 -> 28.14 | G30: =G$19*G$1/G$23 -> 35.31214 | H30: =H$19*H$1/H$23 -> 37.025627 | I30: =I$19*I$1/I$23 -> 23.263083 | J30: =J$19*J$1/J$23 -> 21.11 | ... V30: =V$19*V$1/V$23 -> 9.8382185
A31: Earnings Per Share (EPS) (YTD) | C31: =IF(LEFT(C$2,2)="1Q",C$30,IF(LEFT(C$2,2)="1H",SUM(C$30:D$30),IF(LEFT(C$2,2)="9M",SUM(C$30:E$30),SUM(C$30:F$30)))) -> 141.07 | D31: =IF(LEFT(D$2,2)="1Q",D$30,IF(LEFT(D$2,2)="1H",SUM(D$30:E$30),IF(LEFT(D$2,2)="9M",SUM(D$30:F$30),SUM(D$30:G$30)))) -> 104.64981 | E31: =IF(LEFT(E$2,2)="1Q",E$30,IF(LEFT(E$2,2)="1H",SUM(E$30:F$30),IF(LEFT(E$2,2)="9M",SUM(E$30:G$30),SUM(E$30:H$30)))) -> 62.609227 | F31: =IF(LEFT(F$2,2)="1Q",F$30,IF(LEFT(F$2,2)="1H",SUM(F$30:G$30),IF(LEFT(F$2,2)="9M",SUM(F$30:H$30),SUM(F$30:I$30)))) -> 28.14 | G31: =IF(LEFT(G$2,2)="1Q",G$30,IF(LEFT(G$2,2)="1H",SUM(G$30:H$30),IF(LEFT(G$2,2)="9M",SUM(G$30:I$30),SUM(G$30:J$30)))) -> 116.71085 | H31: =IF(LEFT(H$2,2)="1Q",H$30,IF(LEFT(H$2,2)="1H",SUM(H$30:I$30),IF(LEFT(H$2,2)="9M",SUM(H$30:J$30),SUM(H$30:K$30)))) -> 81.39871 | I31: =IF(LEFT(I$2,2)="1Q",I$30,IF(LEFT(I$2,2)="1H",SUM(I$30:J$30),IF(LEFT(I$2,2)="9M",SUM(I$30:K$30),SUM(I$30:L$30)))) -> 44.373083 | J31: =IF(LEFT(J$2,2)="1Q",J$30,IF(LEFT(J$2,2)="1H",SUM(J$30:K$30),IF(LEFT(J$2,2)="9M",SUM(J$30:L$30),SUM(J$30:M$30)))) -> 21.11 | ... V31: =IF(LEFT(V$2,2)="1Q",V$30,IF(LEFT(V$2,2)="1H",SUM(V$30:W$30),IF(LEFT(V$2,2)="9M",SUM(V$30:X$30),SUM(V$30:Y$30)))) -> 9.8382185
A32: Book Value Per Share (BVPS) | C32: =C$26*C$1/C$23 -> 748.46958 | D32: =D$26*D$1/D$23 -> 738.06558 | E32: =E$26*E$1/E$23 -> 696.09092 | F32: =F$26*F$1/F$23 -> 730.51552 | G32: =G$26*G$1/G$23 -> 702.60576 | H32: =H$26*H$1/H$23 -> 691.53918 | I32: =I$26*I$1/I$23 -> 654.50705 | J32: =J$26*J$1/J$23 -> 693.58202 | ... V32: =V$26*V$1/V$23 -> 562.44154
A34: Valuation
A35: Price Earnings Ratio (PER) (TTM) | B35: =$B$3/SUM(OFFSET($B$30,0,1,1,4)) -> 9.4633872 | C35: =C$3/SUM(C$30:F$30) -> 9.8178212 | D35: =D$3/SUM(D$30:G$30) -> 7.6092111 | E35: =E$3/SUM(E$30:H$30) -> 7.4844201 | F35: =F$3/SUM(F$30:I$30) -> 6.2630894 | G35: =G$3/SUM(G$30:J$30) -> 6.0405695 | H35: =H$3/SUM(H$30:K$30) -> 6.3250964 | I35: =I$3/SUM(I$30:L$30) -> 6.3247515 | J35: =J$3/SUM(J$30:M$30) -> 6.7127304 | ... V35: =V$3/SUM(V$30:Y$30) -> 60.478429
A36: Price Book Value (PBV) | B36: =$B$3/OFFSET($B$32,0,1) -> 1.7836396 | C36: =C$3/C$32 -> 1.8504426 | D36: =D$3/D$32 -> 1.4429612 | E36: =E$3/E$32 -> 1.4509599 | F36: =F$3/F$32 -> 1.0608946 | G36: =G$3/G$32 -> 1.0034077 | H36: =H$3/H$32 -> 0.99054402 | I36: =I$3/I$32 -> 1.0236712 | J36: =J$3/J$32 -> 0.99483548 | ... V36: =V$3/V$32 -> 1.0578877
A37: Price Earnings Growth (PEG) | B37: =B$35/OFFSET($B43,0,1)/100 -> 0.2807569 | C37: =C$35/C$43/100 -> 0.29127214 | D37: =D$35/D$43/100 -> 0.10475635 | E37: =E$35/E$43/100 -> 0.099419592 | F37: =F$35/F$43/100 -> 0.094999123 | G37: =G$35/G$43/100 -> #DIV/0! | H37: =H$35/H$43/100 -> #DIV/0! | I37: =I$35/I$43/100 -> #DIV/0! | J37: =J$35/J$43/100 -> #DIV/0! | ... V37: =V$35/V$43/100 -> #DIV/0!
A39: Profitability
A40: Net Profit Margin (NPM) | C40: =C$20/ABS(C$16) -> 0.27583187 | D40: =D$20/ABS(D$16) -> 0.28822352 | E40: =E$20/ABS(E$16) -> 0.27396622 | F40: =F$20/ABS(F$16) -> 0.25173639 | G40: =G$20/ABS(G$16) -> 0.25735787 | H40: =H$20/ABS(H$16) -> 0.25267704 | I40: =I$20/ABS(I$16) -> 0.22396958 | J40: =J$20/ABS(J$16) -> 0.21856225 | ... V40: =V$20/ABS(V$16) -> 0.14918868
A42: Fair Price Scenario | B42: =B$2 -> Current | C42: =C$2 -> FY2025 | D42: =D$2 -> 9M2025 | E42: =E$2 -> 1H2025 | F42: =F$2 -> 1Q2025 | G42: =G$2 -> FY2024 | H42: =H$2 -> 9M2024 | I42: =I$2 -> 1H2024 | ... V42: =V$2 -> 1Q2021
A43: 5-Year EPS CAGR | C43: =(SUM(C$30:F$30)/SUM(S$30:V$30))^(1/5)-1 -> 0.33706695 | D43: =(SUM(D$30:G$30)/SUM(T$30:W$30))^(1/5)-1 -> 0.72637229 | E43: =(SUM(E$30:H$30)/SUM(U$30:X$30))^(1/5)-1 -> 0.75281139 | F43: =(SUM(F$30:I$30)/SUM(V$30:Y$30))^(1/5)-1 -> 0.65927865 | G43: =(SUM(G$30:J$30)/SUM(W$30:Z$30))^(1/5)-1 -> #DIV/0! | H43: =(SUM(H$30:K$30)/SUM(X$30:AA$30))^(1/5)-1 -> #DIV/0! | I43: =(SUM(I$30:L$30)/SUM(Y$30:AB$30))^(1/5)-1 -> #DIV/0! | J43: =(SUM(J$30:M$30)/SUM(Z$30:AC$30))^(1/5)-1 -> #DIV/0! | ... V43: =(SUM(V$30:Y$30)/SUM(AL$30:AO$30))^(1/5)-1 -> #DIV/0!
A45: Target PER (PEG 1.0x) | B45: =OFFSET($B45,0,1) -> 33.706695 | C45: =C$43*100 -> 33.706695 | D45: =D$43*100 -> 72.637229 | E45: =E$43*100 -> 75.281139 | F45: =F$43*100 -> 65.927865 | G45: =G$43*100 -> #DIV/0! | H45: =H$43*100 -> #DIV/0! | I45: =I$43*100 -> #DIV/0! | J45: =J$43*100 -> #DIV/0! | ... V45: =V$43*100 -> #DIV/0!
A46: Intrinsic Value | B46: =OFFSET($B46,0,1) -> 4755.0033 | C46: =C$45*SUM(C$30:F$30) -> 4755.0033 | D46: =D$45*SUM(D$30:G$30) -> 10166.448 | E46: =E$45*SUM(E$30:H$30) -> 10158.963 | F46: =F$45*SUM(F$30:I$30) -> 8157.9701 | G46: =G$45*SUM(G$30:J$30) -> #DIV/0! | H46: =H$45*SUM(H$30:K$30) -> #DIV/0! | I46: =I$45*SUM(I$30:L$30) -> #DIV/0! | J46: =J$45*SUM(J$30:M$30) -> #DIV/0! | ... V46: =V$45*SUM(V$30:Y$30) -> #DIV/0!
A47: Upside / (Downside) | B47: =(B$46-B$3)/ABS(B$3) -> 2.5618002 | C47: =(C$46-C$3)/ABS(C$3) -> 2.4332154 | D47: =(D$46-D$3)/ABS(D$3) -> 8.5459605 | E47: =(E$46-E$3)/ABS(E$3) -> 9.0583797 | F47: =(F$46-F$3)/ABS(F$3) -> 9.526413 | G47: =(G$46-G$3)/ABS(G$3) -> #DIV/0! | H47: =(H$46-H$3)/ABS(H$3) -> #DIV/0! | I47: =(I$46-I$3)/ABS(I$3) -> #DIV/0! | ... V47: =(V$46-V$3)/ABS(V$3) -> #DIV/0!

Sheet Example of Q&YTD - Quartely Rep
A1: AAAA | B1: Integrated Freight & Logistics | C1: {=IF(C$7="Local Currency",1,_xlfn.XLOOKUP(C$2,OFFSET(Dashboard!$A:$A,0,MATCH(C$7,Dashboard!$1:$1,0)-1),OFFSET(Dashboard!$A:$A,0,MATCH(C$7,Dashboard!$1:$1,0))))} -> 1 | D1: {=IF(D$7="Local Currency",1,_xlfn.XLOOKUP(D$2,OFFSET(Dashboard!$A:$A,0,MATCH(D$7,Dashboard!$1:$1,0)-1),OFFSET(Dashboard!$A:$A,0,MATCH(D$7,Dashboard!$1:$1,0))))} -> 1 | E1: {=IF(E$7="Local Currency",1,_xlfn.XLOOKUP(E$2,OFFSET(Dashboard!$A:$A,0,MATCH(E$7,Dashboard!$1:$1,0)-1),OFFSET(Dashboard!$A:$A,0,MATCH(E$7,Dashboard!$1:$1,0))))} -> 1 | F1: {=IF(F$7="Local Currency",1,_xlfn.XLOOKUP(F$2,OFFSET(Dashboard!$A:$A,0,MATCH(F$7,Dashboard!$1:$1,0)-1),OFFSET(Dashboard!$A:$A,0,MATCH(F$7,Dashboard!$1:$1,0))))} -> 1 | G1: {=IF(G$7="Local Currency",1,_xlfn.XLOOKUP(G$2,OFFSET(Dashboard!$A:$A,0,MATCH(G$7,Dashboard!$1:$1,0)-1),OFFSET(Dashboard!$A:$A,0,MATCH(G$7,Dashboard!$1:$1,0))))} -> 1 | H1: {=IF(H$7="Local Currency",1,_xlfn.XLOOKUP(H$2,OFFSET(Dashboard!$A:$A,0,MATCH(H$7,Dashboard!$1:$1,0)-1),OFFSET(Dashboard!$A:$A,0,MATCH(H$7,Dashboard!$1:$1,0))))} -> 1 | I1: {=IF(I$7="Local Currency",1,_xlfn.XLOOKUP(I$2,OFFSET(Dashboard!$A:$A,0,MATCH(I$7,Dashboard!$1:$1,0)-1),OFFSET(Dashboard!$A:$A,0,MATCH(I$7,Dashboard!$1:$1,0))))} -> 1 | J1: {=IF(J$7="Local Currency",1,_xlfn.XLOOKUP(J$2,OFFSET(Dashboard!$A:$A,0,MATCH(J$7,Dashboard!$1:$1,0)-1),OFFSET(Dashboard!$A:$A,0,MATCH(J$7,Dashboard!$1:$1,0))))} -> 1 | ... V1: {=IF(V$7="Local Currency",1,_xlfn.XLOOKUP(V$2,OFFSET(Dashboard!$A:$A,0,MATCH(V$7,Dashboard!$1:$1,0)-1),OFFSET(Dashboard!$A:$A,0,MATCH(V$7,Dashboard!$1:$1,0))))} -> 1
A2: Market Data | B2: Current | C2: FY2025 | D2: 9M2025 | E2: 1H2025 | F2: 1Q2025 | G2: FY2024 | H2: 9M2024 | I2: 1H2024 | J2: 1Q2024 | K2: FY2023 | L2: 9M2023 | M2: 1H2023 | N2: 1Q2023 | O2: FY2022 | P2: 9M2022 | Q2: 1H2022 | R2: 1Q2022 | S2: FY2021 | T2: 9M2021 | U2: 1H2021 | V2: 1Q2021
A3: Price | B3: 1335 | C3: 1385 | D3: 1065 | E3: 1010 | F3: 775 | G3: 705 | H3: 685 | I3: 670 | J3: 690 | K3: 715 | L3: 710 | M3: 765 | N3: 625 | O3: 570 | P3: 505 | Q3: 615 | R3: 550 | S3: 515 | T3: 595 | U3: 490 | V3: 595
A5: Market Capitalization | B5: =B$3*OFFSET(B$5,0,1)/OFFSET(B$3,0,1) -> 2427178984665 | C5: =C$23*C$3 -> 2518084564615 | D5: =D$23*D$3 -> 1936684063785 | E5: =E$23*E$3 -> 1836493590860 | F5: =F$23*F$3 -> 1409291726950 | G5: =G$23*G$3 -> 1281580755315 | H5: =H$23*H$3 -> 1245773686145 | I5: =I$23*I$3 -> 1218278165400 | J5: =J$23*J$3 -> 1254740877600 | ... V5: =V$23*V$3 -> 1082036929295
A7: Currency | B7: {=IF(COUNTIF($C7:$7,INDEX($C7:$7,MATCH(TRUE,$C7:$7<>"",0)))=COUNTIF($C7:$7,"<>"),"All "&INDEX($C7:$7,MATCH(TRUE,$C7:$7<>"",0)),INDEX($C7:$7,MATCH(MAX(INDEX(COUNTIF($C7:$7,$C7:$7),0)),INDEX(COUNTIF($C7:$7,$C7:$7),0),0))&" Dominant")} -> All Local Currency | C7: Local Currency | D7: Local Currency | E7: Local Currency | F7: Local Currency | G7: Local Currency | H7: Local Currency | I7: Local Currency | J7: Local Currency | K7: Local Currency | L7: Local Currency | M7: Local Currency | N7: Local Currency | O7: Local Currency | P7: Local Currency | Q7: Local Currency | R7: Local Currency | S7: Local Currency | T7: Local Currency | U7: Local Currency | V7: Local Currency
A9: Consolidated Statements of Income | B9: =B$2 -> Current | C9: =C$2 -> FY2025 | D9: =D$2 -> 9M2025 | E9: =E$2 -> 1H2025 | F9: =F$2 -> 1Q2025 | G9: =G$2 -> FY2024 | H9: =H$2 -> 9M2024 | I9: =I$2 -> 1H2024 | ... V9: =V$2 -> 1Q2021
A10: Period Type | B10: {=IF(COUNTIF($C10:$10,INDEX($C10:$10,MATCH(TRUE,$C10:$10<>"",0)))=COUNTIF($C10:$10,"<>"),"All "&INDEX($C10:$10,MATCH(TRUE,$C10:$10<>"",0)),INDEX($C10:$10,MATCH(MAX(INDEX(COUNTIF($C10:$10,$C10:$10),0)),INDEX(COUNTIF($C10:$10,$C10:$10),0),0))&" Dominant")} -> Quarterly Dominant | C10: Quarterly | D10: YTD | E10: Quarterly | F10: YTD | G10: Quarterly | H10: YTD | I10: YTD | J10: Quarterly | K10: YTD | L10: Quarterly | M10: YTD | N10: Quarterly | O10: YTD | P10: Quarterly | Q10: YTD | R10: Quarterly | S10: YTD | T10: Quarterly | U10: YTD | V10: Quarterly
A12: Revenue | C12: 269720224000 | D12: 660240192000 | E12: 212278201000 | F12: 203271873000 | G12: 238772010000 | H12: 585823826000 | I12: 360261682000 | J12: 175637819000 | K12: 735204940000 | L12: 181201900000 | M12: 366960224000 | N12: 191151747000 | O12: 726573259000 | P12: 206003408000 | Q12: 302336582000 | R12: 150046126000 | S12: 516836950000 | T12: 114487473000 | U12: 233284768000 | V12: 119923887000
A13: Net Income | C13: 66215970000 | D13: 190296750000 | E13: 62675757000 | F13: 51170928000 | G13: 64191999000 | H13: 148024228000 | I13: 80687656000 | J13: 38387797000 | K13: 190854844000 | L13: 63025448000 | M13: 78917489000 | N13: 42333996000 | O13: 161724767000 | P13: 63479716000 | Q13: 45415809000 | R13: 35264224000 | S13: 60056174000 | T13: 1763922000 | U13: 14832433000 | V13: 17891287000
A15: Revenue (Quarterly) | C15: =IF(C$10="Quarterly",C$12,IF(LEFT(C$2,2)="1Q",C$16,C$16-D$16)) -> 269720224000 | D15: =IF(D$10="Quarterly",D$12,IF(LEFT(D$2,2)="1Q",D$16,D$16-E$16)) -> 244690118000 | E15: =IF(E$10="Quarterly",E$12,IF(LEFT(E$2,2)="1Q",E$16,E$16-F$16)) -> 212278201000 | F15: =IF(F$10="Quarterly",F$12,IF(LEFT(F$2,2)="1Q",F$16,F$16-G$16)) -> 203271873000 | G15: =IF(G$10="Quarterly",G$12,IF(LEFT(G$2,2)="1Q",G$16,G$16-H$16)) -> 238772010000 | H15: =IF(H$10="Quarterly",H$12,IF(LEFT(H$2,2)="1Q",H$16,H$16-I$16)) -> 225562144000 | I15: =IF(I$10="Quarterly",I$12,IF(LEFT(I$2,2)="1Q",I$16,I$16-J$16)) -> 184623863000 | J15: =IF(J$10="Quarterly",J$12,IF(LEFT(J$2,2)="1Q",J$16,J$16-K$16)) -> 175637819000 | ... V15: =IF(V$10="Quarterly",V$12,IF(LEFT(V$2,2)="1Q",V$16,V$16-W$16)) -> 119923887000
A16: Revenue (YTD) | C16: =IF(C$10="YTD",C$12,IF(LEFT(C$2,2)="1Q",C$15,IF(LEFT(C$2,2)="1H",SUM(C$15:D$15),IF(LEFT(C$2,2)="9M",SUM(C$15:E$15),SUM(C$15:F$15))))) -> 929960416000 | D16: =IF(D$10="YTD",D$12,IF(LEFT(D$2,2)="1Q",D$15,IF(LEFT(D$2,2)="1H",SUM(D$15:E$15),IF(LEFT(D$2,2)="9M",SUM(D$15:F$15),SUM(D$15:G$15))))) -> 660240192000 | E16: =IF(E$10="YTD",E$12,IF(LEFT(E$2,2)="1Q",E$15,IF(LEFT(E$2,2)="1H",SUM(E$15:F$15),IF(LEFT(E$2,2)="9M",SUM(E$15:G$15),SUM(E$15:H$15))))) -> 415550074000 | F16: =IF(F$10="YTD",F$12,IF(LEFT(F$2,2)="1Q",F$15,IF(LEFT(F$2,2)="1H",SUM(F$15:G$15),IF(LEFT(F$2,2)="9M",SUM(F$15:H$15),SUM(F$15:I$15))))) -> 203271873000 | G16: =IF(G$10="YTD",G$12,IF(LEFT(G$2,2)="1Q",G$15,IF(LEFT(G$2,2)="1H",SUM(G$15:H$15),IF(LEFT(G$2,2)="9M",SUM(G$15:I$15),SUM(G$15:J$15))))) -> 824595836000 | H16: =IF(H$10="YTD",H$12,IF(LEFT(H$2,2)="1Q",H$15,IF(LEFT(H$2,2)="1H",SUM(H$15:I$15),IF(LEFT(H$2,2)="9M",SUM(H$15:J$15),SUM(H$15:K$15))))) -> 585823826000 | I16: =IF(I$10="YTD",I$12,IF(LEFT(I$2,2)="1Q",I$15,IF(LEFT(I$2,2)="1H",SUM(I$15:J$15),IF(LEFT(I$2,2)="9M",SUM(I$15:K$15),SUM(I$15:L$15))))) -> 360261682000 | J16: =IF(J$10="YTD",J$12,IF(LEFT(J$2,2)="1Q",J$15,IF(LEFT(J$2,2)="1H",SUM(J$15:K$15),IF(LEFT(J$2,2)="9M",SUM(J$15:L$15),SUM(J$15:M$15))))) -> 175637819000 | ... V16: =IF(V$10="YTD",V$12,IF(LEFT(V$2,2)="1Q",V$15,IF(LEFT(V$2,2)="1H",SUM(V$15:W$15),IF(LEFT(V$2,2)="9M",SUM(V$15:X$15),SUM(V$15:Y$15))))) -> 119923887000
A17: Revenue Growth (YoY) | C17: =(C$16-G$16)/ABS(G$16) -> 0.12777724 | D17: =(D$16-H$16)/ABS(H$16) -> 0.12702858 | E17: =(E$16-I$16)/ABS(I$16) -> 0.15346731 | F17: =(F$16-J$16)/ABS(J$16) -> 0.15733544 | G17: =(G$16-K$16)/ABS(K$16) -> 0.12158636 | H17: =(H$16-L$16)/ABS(L$16) -> 0.068705407 | I17: =(I$16-M$16)/ABS(M$16) -> -0.018254136 | J17: =(J$16-N$16)/ABS(N$16) -> -0.081160273 | ... V17: =(V$16-Z$16)/ABS(Z$16) -> #DIV/0!
A19: Net Income (Quarterly) | C19: =IF(C$10="Quarterly",C$13,IF(LEFT(C$2,2)="1Q",C$20,C$20-D$20)) -> 66215970000 | D19: =IF(D$10="Quarterly",D$13,IF(LEFT(D$2,2)="1Q",D$20,D$20-E$20)) -> 76450065000 | E19: =IF(E$10="Quarterly",E$13,IF(LEFT(E$2,2)="1Q",E$20,E$20-F$20)) -> 62675757000 | F19: =IF(F$10="Quarterly",F$13,IF(LEFT(F$2,2)="1Q",F$20,F$20-G$20)) -> 51170928000 | G19: =IF(G$10="Quarterly",G$13,IF(LEFT(G$2,2)="1Q",G$20,G$20-H$20)) -> 64191999000 | H19: =IF(H$10="Quarterly",H$13,IF(LEFT(H$2,2)="1Q",H$20,H$20-I$20)) -> 67336572000 | I19: =IF(I$10="Quarterly",I$13,IF(LEFT(I$2,2)="1Q",I$20,I$20-J$20)) -> 42299859000 | J19: =IF(J$10="Quarterly",J$13,IF(LEFT(J$2,2)="1Q",J$20,J$20-K$20)) -> 38387797000 | ... V19: =IF(V$10="Quarterly",V$13,IF(LEFT(V$2,2)="1Q",V$20,V$20-W$20)) -> 17891287000
A20: Net Income (YTD) | C20: =IF(C$10="YTD",C$13,IF(LEFT(C$2,2)="1Q",C$19,IF(LEFT(C$2,2)="1H",SUM(C$19:D$19),IF(LEFT(C$2,2)="9M",SUM(C$19:E$19),SUM(C$19:F$19))))) -> 256512720000 | D20: =IF(D$10="YTD",D$13,IF(LEFT(D$2,2)="1Q",D$19,IF(LEFT(D$2,2)="1H",SUM(D$19:E$19),IF(LEFT(D$2,2)="9M",SUM(D$19:F$19),SUM(D$19:G$19))))) -> 190296750000 | E20: =IF(E$10="YTD",E$13,IF(LEFT(E$2,2)="1Q",E$19,IF(LEFT(E$2,2)="1H",SUM(E$19:F$19),IF(LEFT(E$2,2)="9M",SUM(E$19:G$19),SUM(E$19:H$19))))) -> 113846685000 | F20: =IF(F$10="YTD",F$13,IF(LEFT(F$2,2)="1Q",F$19,IF(LEFT(F$2,2)="1H",SUM(F$19:G$19),IF(LEFT(F$2,2)="9M",SUM(F$19:H$19),SUM(F$19:I$19))))) -> 51170928000 | G20: =IF(G$10="YTD",G$13,IF(LEFT(G$2,2)="1Q",G$19,IF(LEFT(G$2,2)="1H",SUM(G$19:H$19),IF(LEFT(G$2,2)="9M",SUM(G$19:I$19),SUM(G$19:J$19))))) -> 212216227000 | H20: =IF(H$10="YTD",H$13,IF(LEFT(H$2,2)="1Q",H$19,IF(LEFT(H$2,2)="1H",SUM(H$19:I$19),IF(LEFT(H$2,2)="9M",SUM(H$19:J$19),SUM(H$19:K$19))))) -> 148024228000 | I20: =IF(I$10="YTD",I$13,IF(LEFT(I$2,2)="1Q",I$19,IF(LEFT(I$2,2)="1H",SUM(I$19:J$19),IF(LEFT(I$2,2)="9M",SUM(I$19:K$19),SUM(I$19:L$19))))) -> 80687656000 | J20: =IF(J$10="YTD",J$13,IF(LEFT(J$2,2)="1Q",J$19,IF(LEFT(J$2,2)="1H",SUM(J$19:K$19),IF(LEFT(J$2,2)="9M",SUM(J$19:L$19),SUM(J$19:M$19))))) -> 38387797000 | ... V20: =IF(V$10="YTD",V$13,IF(LEFT(V$2,2)="1Q",V$19,IF(LEFT(V$2,2)="1H",SUM(V$19:W$19),IF(LEFT(V$2,2)="9M",SUM(V$19:X$19),SUM(V$19:Y$19))))) -> 17891287000
A21: Net Income Growth (YoY) | C21: =(C$20-G$20)/ABS(G$20) -> 0.20873283 | D21: =(D$20-H$20)/ABS(H$20) -> 0.2855784 | E21: =(E$20-I$20)/ABS(I$20) -> 0.41095541 | F21: =(F$20-J$20)/ABS(J$20) -> 0.33299986 | G21: =(G$20-K$20)/ABS(K$20) -> 0.11192476 | H21: =(H$20-L$20)/ABS(L$20) -> 0.04284321 | I21: =(I$20-M$20)/ABS(M$20) -> 0.022430605 | J21: =(J$20-N$20)/ABS(N$20) -> -0.09321584 | ... V21: =(V$20-Z$20)/ABS(Z$20) -> #DIV/0!
A23: Shares Outstanding | C23: 1818111599 | D23: 1818482689 | E23: 1818310486 | F23: 1818440938 | G23: 1817845043 | H23: 1818647717 | I23: 1818325620 | J23: 1818465040 | K23: 1818284091 | L23: 1818396817 | M23: 1818280026 | N23: 1818470618 | O23: 1818277789 | P23: 1818384807 | Q23: 1818088723 | R23: 1818680969 | S23: 1819576943 | T23: 1816577843 | U23: 1818549461 | V23: 1818549461
A25: Consolidated Balance Sheets | B25: =B$2 -> Current | C25: =C$2 -> FY2025 | D25: =D$2 -> 9M2025 | E25: =E$2 -> 1H2025 | F25: =F$2 -> 1Q2025 | G25: =G$2 -> FY2024 | H25: =H$2 -> 9M2024 | I25: =I$2 -> 1H2024 | ... V25: =V$2 -> 1Q2021
A26: Shareholders' Equity | C26: 1360801231000 | D26: 1342159480000 | E26: 1265709415000 | F26: 1328399319000 | G26: 1277228391000 | H26: 1257666157000 | I26: 1190106935000 | J26: 1261254651000 | K26: 1222866854000 | L26: 1213408389000 | M26: 1240883954000 | N26: 1204304183000 | O26: 1161970187000 | P26: 1131848849000 | Q26: 1110408454000 | R26: 1100256869000 | S26: 1064992645000 | T26: 1021532826000 | U26: 1019768905000 | V26: 1022827759000
A28: Ratio Analysis | B28: =B$2 -> Current | C28: =C$2 -> FY2025 | D28: =D$2 -> 9M2025 | E28: =E$2 -> 1H2025 | F28: =F$2 -> 1Q2025 | G28: =G$2 -> FY2024 | H28: =H$2 -> 9M2024 | I28: =I$2 -> 1H2024 | ... V28: =V$2 -> 1Q2021
A29: Earnings
A30: Earnings Per Share (EPS) (Quarterly) | C30: =C$19*C$1/C$23 -> 36.42019 | D30: =D$19*D$1/D$23 -> 42.040579 | E30: =E$19*E$1/E$23 -> 34.469227 | F30: =F$19*F$1/F$23 -> 28.14 | G30: =G$19*G$1/G$23 -> 35.31214 | H30: =H$19*H$1/H$23 -> 37.025627 | I30: =I$19*I$1/I$23 -> 23.263083 | J30: =J$19*J$1/J$23 -> 21.11 | ... V30: =V$19*V$1/V$23 -> 9.8382185
A31: Earnings Per Share (EPS) (YTD) | C31: =IF(LEFT(C$2,2)="1Q",C$30,IF(LEFT(C$2,2)="1H",SUM(C$30:D$30),IF(LEFT(C$2,2)="9M",SUM(C$30:E$30),SUM(C$30:F$30)))) -> 141.07 | D31: =IF(LEFT(D$2,2)="1Q",D$30,IF(LEFT(D$2,2)="1H",SUM(D$30:E$30),IF(LEFT(D$2,2)="9M",SUM(D$30:F$30),SUM(D$30:G$30)))) -> 104.64981 | E31: =IF(LEFT(E$2,2)="1Q",E$30,IF(LEFT(E$2,2)="1H",SUM(E$30:F$30),IF(LEFT(E$2,2)="9M",SUM(E$30:G$30),SUM(E$30:H$30)))) -> 62.609227 | F31: =IF(LEFT(F$2,2)="1Q",F$30,IF(LEFT(F$2,2)="1H",SUM(F$30:G$30),IF(LEFT(F$2,2)="9M",SUM(F$30:H$30),SUM(F$30:I$30)))) -> 28.14 | G31: =IF(LEFT(G$2,2)="1Q",G$30,IF(LEFT(G$2,2)="1H",SUM(G$30:H$30),IF(LEFT(G$2,2)="9M",SUM(G$30:I$30),SUM(G$30:J$30)))) -> 116.71085 | H31: =IF(LEFT(H$2,2)="1Q",H$30,IF(LEFT(H$2,2)="1H",SUM(H$30:I$30),IF(LEFT(H$2,2)="9M",SUM(H$30:J$30),SUM(H$30:K$30)))) -> 81.39871 | I31: =IF(LEFT(I$2,2)="1Q",I$30,IF(LEFT(I$2,2)="1H",SUM(I$30:J$30),IF(LEFT(I$2,2)="9M",SUM(I$30:K$30),SUM(I$30:L$30)))) -> 44.373083 | J31: =IF(LEFT(J$2,2)="1Q",J$30,IF(LEFT(J$2,2)="1H",SUM(J$30:K$30),IF(LEFT(J$2,2)="9M",SUM(J$30:L$30),SUM(J$30:M$30)))) -> 21.11 | ... V31: =IF(LEFT(V$2,2)="1Q",V$30,IF(LEFT(V$2,2)="1H",SUM(V$30:W$30),IF(LEFT(V$2,2)="9M",SUM(V$30:X$30),SUM(V$30:Y$30)))) -> 9.8382185
A32: Book Value Per Share (BVPS) | C32: =C$26*C$1/C$23 -> 748.46958 | D32: =D$26*D$1/D$23 -> 738.06558 | E32: =E$26*E$1/E$23 -> 696.09092 | F32: =F$26*F$1/F$23 -> 730.51552 | G32: =G$26*G$1/G$23 -> 702.60576 | H32: =H$26*H$1/H$23 -> 691.53918 | I32: =I$26*I$1/I$23 -> 654.50705 | J32: =J$26*J$1/J$23 -> 693.58202 | ... V32: =V$26*V$1/V$23 -> 562.44154
A34: Valuation
A35: Price Earnings Ratio (PER) (TTM) | B35: =$B$3/SUM(OFFSET($B$30,0,1,1,4)) -> 9.4633872 | C35: =C$3/SUM(C$30:F$30) -> 9.8178212 | D35: =D$3/SUM(D$30:G$30) -> 7.6092111 | E35: =E$3/SUM(E$30:H$30) -> 7.4844201 | F35: =F$3/SUM(F$30:I$30) -> 6.2630894 | G35: =G$3/SUM(G$30:J$30) -> 6.0405695 | H35: =H$3/SUM(H$30:K$30) -> 6.3250964 | I35: =I$3/SUM(I$30:L$30) -> 6.3247515 | J35: =J$3/SUM(J$30:M$30) -> 6.7127304 | ... V35: =V$3/SUM(V$30:Y$30) -> 60.478429
A36: Price Book Value (PBV) | B36: =$B$3/OFFSET($B$32,0,1) -> 1.7836396 | C36: =C$3/C$32 -> 1.8504426 | D36: =D$3/D$32 -> 1.4429612 | E36: =E$3/E$32 -> 1.4509599 | F36: =F$3/F$32 -> 1.0608946 | G36: =G$3/G$32 -> 1.0034077 | H36: =H$3/H$32 -> 0.99054402 | I36: =I$3/I$32 -> 1.0236712 | J36: =J$3/J$32 -> 0.99483548 | ... V36: =V$3/V$32 -> 1.0578877
A37: Price Earnings Growth (PEG) | B37: =B$35/OFFSET($B43,0,1)/100 -> 0.2807569 | C37: =C$35/C$43/100 -> 0.29127214 | D37: =D$35/D$43/100 -> 0.10475635 | E37: =E$35/E$43/100 -> 0.099419592 | F37: =F$35/F$43/100 -> 0.094999123 | G37: =G$35/G$43/100 -> #DIV/0! | H37: =H$35/H$43/100 -> #DIV/0! | I37: =I$35/I$43/100 -> #DIV/0! | J37: =J$35/J$43/100 -> #DIV/0! | ... V37: =V$35/V$43/100 -> #DIV/0!
A39: Profitability
A40: Net Profit Margin (NPM) | C40: =C$20/ABS(C$16) -> 0.27583187 | D40: =D$20/ABS(D$16) -> 0.28822352 | E40: =E$20/ABS(E$16) -> 0.27396622 | F40: =F$20/ABS(F$16) -> 0.25173639 | G40: =G$20/ABS(G$16) -> 0.25735787 | H40: =H$20/ABS(H$16) -> 0.25267704 | I40: =I$20/ABS(I$16) -> 0.22396958 | J40: =J$20/ABS(J$16) -> 0.21856225 | ... V40: =V$20/ABS(V$16) -> 0.14918868
A42: Fair Price Scenario | B42: =B$2 -> Current | C42: =C$2 -> FY2025 | D42: =D$2 -> 9M2025 | E42: =E$2 -> 1H2025 | F42: =F$2 -> 1Q2025 | G42: =G$2 -> FY2024 | H42: =H$2 -> 9M2024 | I42: =I$2 -> 1H2024 | ... V42: =V$2 -> 1Q2021
A43: 5-Year EPS CAGR | C43: =(SUM(C$30:F$30)/SUM(S$30:V$30))^(1/5)-1 -> 0.33706695 | D43: =(SUM(D$30:G$30)/SUM(T$30:W$30))^(1/5)-1 -> 0.72637229 | E43: =(SUM(E$30:H$30)/SUM(U$30:X$30))^(1/5)-1 -> 0.75281139 | F43: =(SUM(F$30:I$30)/SUM(V$30:Y$30))^(1/5)-1 -> 0.65927865 | G43: =(SUM(G$30:J$30)/SUM(W$30:Z$30))^(1/5)-1 -> #DIV/0! | H43: =(SUM(H$30:K$30)/SUM(X$30:AA$30))^(1/5)-1 -> #DIV/0! | I43: =(SUM(I$30:L$30)/SUM(Y$30:AB$30))^(1/5)-1 -> #DIV/0! | J43: =(SUM(J$30:M$30)/SUM(Z$30:AC$30))^(1/5)-1 -> #DIV/0! | ... V43: =(SUM(V$30:Y$30)/SUM(AL$30:AO$30))^(1/5)-1 -> #DIV/0!
A45: Target PER (PEG 1.0x) | B45: =OFFSET($B45,0,1) -> 33.706695 | C45: =C$43*100 -> 33.706695 | D45: =D$43*100 -> 72.637229 | E45: =E$43*100 -> 75.281139 | F45: =F$43*100 -> 65.927865 | G45: =G$43*100 -> #DIV/0! | H45: =H$43*100 -> #DIV/0! | I45: =I$43*100 -> #DIV/0! | J45: =J$43*100 -> #DIV/0! | ... V45: =V$43*100 -> #DIV/0!
A46: Intrinsic Value | B46: =OFFSET($B46,0,1) -> 4755.0033 | C46: =C$45*SUM(C$30:F$30) -> 4755.0033 | D46: =D$45*SUM(D$30:G$30) -> 10166.448 | E46: =E$45*SUM(E$30:H$30) -> 10158.963 | F46: =F$45*SUM(F$30:I$30) -> 8157.9701 | G46: =G$45*SUM(G$30:J$30) -> #DIV/0! | H46: =H$45*SUM(H$30:K$30) -> #DIV/0! | I46: =I$45*SUM(I$30:L$30) -> #DIV/0! | J46: =J$45*SUM(J$30:M$30) -> #DIV/0! | ... V46: =V$45*SUM(V$30:Y$30) -> #DIV/0!
A47: Upside / (Downside) | B47: =(B$46-B$3)/ABS(B$3) -> 2.5618002 | C47: =(C$46-C$3)/ABS(C$3) -> 2.4332154 | D47: =(D$46-D$3)/ABS(D$3) -> 8.5459605 | E47: =(E$46-E$3)/ABS(E$3) -> 9.0583797 | F47: =(F$46-F$3)/ABS(F$3) -> 9.526413 | G47: =(G$46-G$3)/ABS(G$3) -> #DIV/0! | H47: =(H$46-H$3)/ABS(H$3) -> #DIV/0! | I47: =(I$46-I$3)/ABS(I$3) -> #DIV/0! | ... V47: =(V$46-V$3)/ABS(V$3) -> #DIV/0!

Sheet Quarterly - Quartely Report
A1: AAAA | B1: Integrated Freight & Logistics | C1: {=IF(C$7="Local Currency",1,_xlfn.XLOOKUP(C$2,OFFSET(Dashboard!$A:$A,0,MATCH(C$7,Dashboard!$1:$1,0)-1),OFFSET(Dashboard!$A:$A,0,MATCH(C$7,Dashboard!$1:$1,0))))} -> 1 | D1: {=IF(D$7="Local Currency",1,_xlfn.XLOOKUP(D$2,OFFSET(Dashboard!$A:$A,0,MATCH(D$7,Dashboard!$1:$1,0)-1),OFFSET(Dashboard!$A:$A,0,MATCH(D$7,Dashboard!$1:$1,0))))} -> 1 | E1: {=IF(E$7="Local Currency",1,_xlfn.XLOOKUP(E$2,OFFSET(Dashboard!$A:$A,0,MATCH(E$7,Dashboard!$1:$1,0)-1),OFFSET(Dashboard!$A:$A,0,MATCH(E$7,Dashboard!$1:$1,0))))} -> 1 | F1: {=IF(F$7="Local Currency",1,_xlfn.XLOOKUP(F$2,OFFSET(Dashboard!$A:$A,0,MATCH(F$7,Dashboard!$1:$1,0)-1),OFFSET(Dashboard!$A:$A,0,MATCH(F$7,Dashboard!$1:$1,0))))} -> 1 | G1: {=IF(G$7="Local Currency",1,_xlfn.XLOOKUP(G$2,OFFSET(Dashboard!$A:$A,0,MATCH(G$7,Dashboard!$1:$1,0)-1),OFFSET(Dashboard!$A:$A,0,MATCH(G$7,Dashboard!$1:$1,0))))} -> 1 | H1: {=IF(H$7="Local Currency",1,_xlfn.XLOOKUP(H$2,OFFSET(Dashboard!$A:$A,0,MATCH(H$7,Dashboard!$1:$1,0)-1),OFFSET(Dashboard!$A:$A,0,MATCH(H$7,Dashboard!$1:$1,0))))} -> 1 | I1: {=IF(I$7="Local Currency",1,_xlfn.XLOOKUP(I$2,OFFSET(Dashboard!$A:$A,0,MATCH(I$7,Dashboard!$1:$1,0)-1),OFFSET(Dashboard!$A:$A,0,MATCH(I$7,Dashboard!$1:$1,0))))} -> 1 | J1: {=IF(J$7="Local Currency",1,_xlfn.XLOOKUP(J$2,OFFSET(Dashboard!$A:$A,0,MATCH(J$7,Dashboard!$1:$1,0)-1),OFFSET(Dashboard!$A:$A,0,MATCH(J$7,Dashboard!$1:$1,0))))} -> 1 | ... V1: {=IF(V$7="Local Currency",1,_xlfn.XLOOKUP(V$2,OFFSET(Dashboard!$A:$A,0,MATCH(V$7,Dashboard!$1:$1,0)-1),OFFSET(Dashboard!$A:$A,0,MATCH(V$7,Dashboard!$1:$1,0))))} -> 1
A2: Market Data | B2: Current | C2: FY2025 | D2: 9M2025 | E2: 1H2025 | F2: 1Q2025 | G2: FY2024 | H2: 9M2024 | I2: 1H2024 | J2: 1Q2024 | K2: FY2023 | L2: 9M2023 | M2: 1H2023 | N2: 1Q2023 | O2: FY2022 | P2: 9M2022 | Q2: 1H2022 | R2: 1Q2022 | S2: FY2021 | T2: 9M2021 | U2: 1H2021 | V2: 1Q2021
A3: Price | B3: 1335 | C3: 1385 | D3: 1065 | E3: 1010 | F3: 775 | G3: 705 | H3: 685 | I3: 670 | J3: 690 | K3: 715 | L3: 710 | M3: 765 | N3: 625 | O3: 570 | P3: 505 | Q3: 615 | R3: 550 | S3: 515 | T3: 595 | U3: 490 | V3: 595
A5: Market Capitalization | B5: =B$3*OFFSET(B$5,0,1)/OFFSET(B$3,0,1) -> 2427178984665 | C5: =C$19*C$3 -> 2518084564615 | D5: =D$19*D$3 -> 1936684063785 | E5: =E$19*E$3 -> 1836493590860 | F5: =F$19*F$3 -> 1409291726950 | G5: =G$19*G$3 -> 1281580755315 | H5: =H$19*H$3 -> 1245773686145 | I5: =I$19*I$3 -> 1218278165400 | J5: =J$19*J$3 -> 1254740877600 | ... V5: =V$19*V$3 -> 1082036929295
A7: Currency | B7: {=IF(COUNTIF($C7:$7,INDEX($C7:$7,MATCH(TRUE,$C7:$7<>"",0)))=COUNTIF($C7:$7,"<>"),"All "&INDEX($C7:$7,MATCH(TRUE,$C7:$7<>"",0)),INDEX($C7:$7,MATCH(MAX(INDEX(COUNTIF($C7:$7,$C7:$7),0)),INDEX(COUNTIF($C7:$7,$C7:$7),0),0))&" Dominant")} -> All Local Currency | C7: Local Currency | D7: Local Currency | E7: Local Currency | F7: Local Currency | G7: Local Currency | H7: Local Currency | I7: Local Currency | J7: Local Currency | K7: Local Currency | L7: Local Currency | M7: Local Currency | N7: Local Currency | O7: Local Currency | P7: Local Currency | Q7: Local Currency | R7: Local Currency | S7: Local Currency | T7: Local Currency | U7: Local Currency | V7: Local Currency
A9: Consolidated Statements of Income | B9: =B$2 -> Current | C9: =C$2 -> FY2025 | D9: =D$2 -> 9M2025 | E9: =E$2 -> 1H2025 | F9: =F$2 -> 1Q2025 | G9: =G$2 -> FY2024 | H9: =H$2 -> 9M2024 | I9: =I$2 -> 1H2024 | ... V9: =V$2 -> 1Q2021
A10: Revenue | C10: 269720224000 | D10: 244690118000 | E10: 212278201000 | F10: 203271873000 | G10: 238772010000 | H10: 225562144000 | I10: 184623863000 | J10: 175637819000 | K10: 187042816000 | L10: 181201900000 | M10: 175808477000 | N10: 191151747000 | O10: 218233269000 | P10: 206003408000 | Q10: 152290456000 | R10: 150046126000 | S10: 169064709000 | T10: 114487473000 | U10: 113360881000 | V10: 119923887000
A11: Net Income | C11: 66215970000 | D11: 76450065000 | E11: 62675757000 | F11: 51170928000 | G11: 64191999000 | H11: 67336572000 | I11: 42299859000 | J11: 38387797000 | K11: 48911907000 | L11: 63025448000 | M11: 36583493000 | N11: 42333996000 | O11: 52829242000 | P11: 63479716000 | Q11: 10151585000 | R11: 35264224000 | S11: 43459819000 | T11: 1763922000 | U11: -3058854000 | V11: 17891287000
A13: Revenue (YTD) | C13: =IF(LEFT(C$2,2)="1Q",C$10,IF(LEFT(C$2,2)="1H",SUM(C$10:D$10),IF(LEFT(C$2,2)="9M",SUM(C$10:E$10),SUM(C$10:F$10)))) -> 929960416000 | D13: =IF(LEFT(D$2,2)="1Q",D$10,IF(LEFT(D$2,2)="1H",SUM(D$10:E$10),IF(LEFT(D$2,2)="9M",SUM(D$10:F$10),SUM(D$10:G$10)))) -> 660240192000 | E13: =IF(LEFT(E$2,2)="1Q",E$10,IF(LEFT(E$2,2)="1H",SUM(E$10:F$10),IF(LEFT(E$2,2)="9M",SUM(E$10:G$10),SUM(E$10:H$10)))) -> 415550074000 | F13: =IF(LEFT(F$2,2)="1Q",F$10,IF(LEFT(F$2,2)="1H",SUM(F$10:G$10),IF(LEFT(F$2,2)="9M",SUM(F$10:H$10),SUM(F$10:I$10)))) -> 203271873000 | G13: =IF(LEFT(G$2,2)="1Q",G$10,IF(LEFT(G$2,2)="1H",SUM(G$10:H$10),IF(LEFT(G$2,2)="9M",SUM(G$10:I$10),SUM(G$10:J$10)))) -> 824595836000 | H13: =IF(LEFT(H$2,2)="1Q",H$10,IF(LEFT(H$2,2)="1H",SUM(H$10:I$10),IF(LEFT(H$2,2)="9M",SUM(H$10:J$10),SUM(H$10:K$10)))) -> 585823826000 | I13: =IF(LEFT(I$2,2)="1Q",I$10,IF(LEFT(I$2,2)="1H",SUM(I$10:J$10),IF(LEFT(I$2,2)="9M",SUM(I$10:K$10),SUM(I$10:L$10)))) -> 360261682000 | J13: =IF(LEFT(J$2,2)="1Q",J$10,IF(LEFT(J$2,2)="1H",SUM(J$10:K$10),IF(LEFT(J$2,2)="9M",SUM(J$10:L$10),SUM(J$10:M$10)))) -> 175637819000 | ... V13: =IF(LEFT(V$2,2)="1Q",V$10,IF(LEFT(V$2,2)="1H",SUM(V$10:W$10),IF(LEFT(V$2,2)="9M",SUM(V$10:X$10),SUM(V$10:Y$10)))) -> 119923887000
A14: Revenue Growth (YoY) | C14: =(C$13-G$13)/ABS(G$13) -> 0.12777724 | D14: =(D$13-H$13)/ABS(H$13) -> 0.12702858 | E14: =(E$13-I$13)/ABS(I$13) -> 0.15346731 | F14: =(F$13-J$13)/ABS(J$13) -> 0.15733544 | G14: =(G$13-K$13)/ABS(K$13) -> 0.12158636 | H14: =(H$13-L$13)/ABS(L$13) -> 0.068705407 | I14: =(I$13-M$13)/ABS(M$13) -> -0.018254136 | J14: =(J$13-N$13)/ABS(N$13) -> -0.081160273 | ... V14: =(V$13-Z$13)/ABS(Z$13) -> #DIV/0!
A16: Net Income (YTD) | C16: =IF(LEFT(C$2,2)="1Q",C$11,IF(LEFT(C$2,2)="1H",SUM(C$11:D$11),IF(LEFT(C$2,2)="9M",SUM(C$11:E$11),SUM(C$11:F$11)))) -> 256512720000 | D16: =IF(LEFT(D$2,2)="1Q",D$11,IF(LEFT(D$2,2)="1H",SUM(D$11:E$11),IF(LEFT(D$2,2)="9M",SUM(D$11:F$11),SUM(D$11:G$11)))) -> 190296750000 | E16: =IF(LEFT(E$2,2)="1Q",E$11,IF(LEFT(E$2,2)="1H",SUM(E$11:F$11),IF(LEFT(E$2,2)="9M",SUM(E$11:G$11),SUM(E$11:H$11)))) -> 113846685000 | F16: =IF(LEFT(F$2,2)="1Q",F$11,IF(LEFT(F$2,2)="1H",SUM(F$11:G$11),IF(LEFT(F$2,2)="9M",SUM(F$11:H$11),SUM(F$11:I$11)))) -> 51170928000 | G16: =IF(LEFT(G$2,2)="1Q",G$11,IF(LEFT(G$2,2)="1H",SUM(G$11:H$11),IF(LEFT(G$2,2)="9M",SUM(G$11:I$11),SUM(G$11:J$11)))) -> 212216227000 | H16: =IF(LEFT(H$2,2)="1Q",H$11,IF(LEFT(H$2,2)="1H",SUM(H$11:I$11),IF(LEFT(H$2,2)="9M",SUM(H$11:J$11),SUM(H$11:K$11)))) -> 148024228000 | I16: =IF(LEFT(I$2,2)="1Q",I$11,IF(LEFT(I$2,2)="1H",SUM(I$11:J$11),IF(LEFT(I$2,2)="9M",SUM(I$11:K$11),SUM(I$11:L$11)))) -> 80687656000 | J16: =IF(LEFT(J$2,2)="1Q",J$11,IF(LEFT(J$2,2)="1H",SUM(J$11:K$11),IF(LEFT(J$2,2)="9M",SUM(J$11:L$11),SUM(J$11:M$11)))) -> 38387797000 | ... V16: =IF(LEFT(V$2,2)="1Q",V$11,IF(LEFT(V$2,2)="1H",SUM(V$11:W$11),IF(LEFT(V$2,2)="9M",SUM(V$11:X$11),SUM(V$11:Y$11)))) -> 17891287000
A17: Net Income Growth (YoY) | C17: =(C$16-G$16)/ABS(G$16) -> 0.20873283 | D17: =(D$16-H$16)/ABS(H$16) -> 0.2855784 | E17: =(E$16-I$16)/ABS(I$16) -> 0.41095541 | F17: =(F$16-J$16)/ABS(J$16) -> 0.33299986 | G17: =(G$16-K$16)/ABS(K$16) -> 0.11192476 | H17: =(H$16-L$16)/ABS(L$16) -> 0.04284321 | I17: =(I$16-M$16)/ABS(M$16) -> 0.022430605 | J17: =(J$16-N$16)/ABS(N$16) -> -0.09321584 | ... V17: =(V$16-Z$16)/ABS(Z$16) -> #DIV/0!
A19: Shares Outstanding | C19: 1818111599 | D19: 1818482689 | E19: 1818310486 | F19: 1818440938 | G19: 1817845043 | H19: 1818647717 | I19: 1818325620 | J19: 1818465040 | K19: 1818284091 | L19: 1818396817 | M19: 1818280026 | N19: 1818470618 | O19: 1818277789 | P19: 1818384807 | Q19: 1818088723 | R19: 1818680969 | S19: 1819576943 | T19: 1816577843 | U19: 1818549461 | V19: 1818549461
A21: Consolidated Balance Sheets | B21: =B$2 -> Current | C21: =C$2 -> FY2025 | D21: =D$2 -> 9M2025 | E21: =E$2 -> 1H2025 | F21: =F$2 -> 1Q2025 | G21: =G$2 -> FY2024 | H21: =H$2 -> 9M2024 | I21: =I$2 -> 1H2024 | ... V21: =V$2 -> 1Q2021
A22: Shareholders' Equity | C22: 1360801231000 | D22: 1342159480000 | E22: 1265709415000 | F22: 1328399319000 | G22: 1277228391000 | H22: 1257666157000 | I22: 1190106935000 | J22: 1261254651000 | K22: 1222866854000 | L22: 1213408389000 | M22: 1240883954000 | N22: 1204304183000 | O22: 1161970187000 | P22: 1131848849000 | Q22: 1110408454000 | R22: 1100256869000 | S22: 1064992645000 | T22: 1021532826000 | U22: 1019768905000 | V22: 1022827759000
A24: Ratio Analysis | B24: =B$2 -> Current | C24: =C$2 -> FY2025 | D24: =D$2 -> 9M2025 | E24: =E$2 -> 1H2025 | F24: =F$2 -> 1Q2025 | G24: =G$2 -> FY2024 | H24: =H$2 -> 9M2024 | I24: =I$2 -> 1H2024 | ... V24: =V$2 -> 1Q2021
A25: Earnings
A26: Earnings Per Share (EPS) (Quarterly) | C26: =C$11*C$1/C$19 -> 36.42019 | D26: =D$11*D$1/D$19 -> 42.040579 | E26: =E$11*E$1/E$19 -> 34.469227 | F26: =F$11*F$1/F$19 -> 28.14 | G26: =G$11*G$1/G$19 -> 35.31214 | H26: =H$11*H$1/H$19 -> 37.025627 | I26: =I$11*I$1/I$19 -> 23.263083 | J26: =J$11*J$1/J$19 -> 21.11 | ... V26: =V$11*V$1/V$19 -> 9.8382185
A27: Earnings Per Share (EPS) (YTD) | C27: =IF(LEFT(C$2,2)="1Q",C$26,IF(LEFT(C$2,2)="1H",SUM(C$26:D$26),IF(LEFT(C$2,2)="9M",SUM(C$26:E$26),SUM(C$26:F$26)))) -> 141.07 | D27: =IF(LEFT(D$2,2)="1Q",D$26,IF(LEFT(D$2,2)="1H",SUM(D$26:E$26),IF(LEFT(D$2,2)="9M",SUM(D$26:F$26),SUM(D$26:G$26)))) -> 104.64981 | E27: =IF(LEFT(E$2,2)="1Q",E$26,IF(LEFT(E$2,2)="1H",SUM(E$26:F$26),IF(LEFT(E$2,2)="9M",SUM(E$26:G$26),SUM(E$26:H$26)))) -> 62.609227 | F27: =IF(LEFT(F$2,2)="1Q",F$26,IF(LEFT(F$2,2)="1H",SUM(F$26:G$26),IF(LEFT(F$2,2)="9M",SUM(F$26:H$26),SUM(F$26:I$26)))) -> 28.14 | G27: =IF(LEFT(G$2,2)="1Q",G$26,IF(LEFT(G$2,2)="1H",SUM(G$26:H$26),IF(LEFT(G$2,2)="9M",SUM(G$26:I$26),SUM(G$26:J$26)))) -> 116.71085 | H27: =IF(LEFT(H$2,2)="1Q",H$26,IF(LEFT(H$2,2)="1H",SUM(H$26:I$26),IF(LEFT(H$2,2)="9M",SUM(H$26:J$26),SUM(H$26:K$26)))) -> 81.39871 | I27: =IF(LEFT(I$2,2)="1Q",I$26,IF(LEFT(I$2,2)="1H",SUM(I$26:J$26),IF(LEFT(I$2,2)="9M",SUM(I$26:K$26),SUM(I$26:L$26)))) -> 44.373083 | J27: =IF(LEFT(J$2,2)="1Q",J$26,IF(LEFT(J$2,2)="1H",SUM(J$26:K$26),IF(LEFT(J$2,2)="9M",SUM(J$26:L$26),SUM(J$26:M$26)))) -> 21.11 | ... V27: =IF(LEFT(V$2,2)="1Q",V$26,IF(LEFT(V$2,2)="1H",SUM(V$26:W$26),IF(LEFT(V$2,2)="9M",SUM(V$26:X$26),SUM(V$26:Y$26)))) -> 9.8382185
A28: Book Value Per Share (BVPS) | C28: =C$22*C$1/C$19 -> 748.46958 | D28: =D$22*D$1/D$19 -> 738.06558 | E28: =E$22*E$1/E$19 -> 696.09092 | F28: =F$22*F$1/F$19 -> 730.51552 | G28: =G$22*G$1/G$19 -> 702.60576 | H28: =H$22*H$1/H$19 -> 691.53918 | I28: =I$22*I$1/I$19 -> 654.50705 | J28: =J$22*J$1/J$19 -> 693.58202 | ... V28: =V$22*V$1/V$19 -> 562.44154
A30: Valuation
A31: Price Earnings Ratio (PER) (TTM) | B31: =$B$3/SUM(OFFSET($B$26,0,1,1,4)) -> 9.4633872 | C31: =C$3/SUM(C$26:F$26) -> 9.8178212 | D31: =D$3/SUM(D$26:G$26) -> 7.6092111 | E31: =E$3/SUM(E$26:H$26) -> 7.4844201 | F31: =F$3/SUM(F$26:I$26) -> 6.2630894 | G31: =G$3/SUM(G$26:J$26) -> 6.0405695 | H31: =H$3/SUM(H$26:K$26) -> 6.3250964 | I31: =I$3/SUM(I$26:L$26) -> 6.3247515 | J31: =J$3/SUM(J$26:M$26) -> 6.7127304 | ... V31: =V$3/SUM(V$26:Y$26) -> 60.478429
A32: Price Book Value (PBV) | B32: =$B$3/OFFSET($B$28,0,1) -> 1.7836396 | C32: =C$3/C$28 -> 1.8504426 | D32: =D$3/D$28 -> 1.4429612 | E32: =E$3/E$28 -> 1.4509599 | F32: =F$3/F$28 -> 1.0608946 | G32: =G$3/G$28 -> 1.0034077 | H32: =H$3/H$28 -> 0.99054402 | I32: =I$3/I$28 -> 1.0236712 | J32: =J$3/J$28 -> 0.99483548 | ... V32: =V$3/V$28 -> 1.0578877
A33: Price Earnings Growth (PEG) | B33: =B$31/OFFSET($B39,0,1)/100 -> 0.2807569 | C33: =C$31/C$39/100 -> 0.29127214 | D33: =D$31/D$39/100 -> 0.10475635 | E33: =E$31/E$39/100 -> 0.099419592 | F33: =F$31/F$39/100 -> 0.094999123 | G33: =G$31/G$39/100 -> #DIV/0! | H33: =H$31/H$39/100 -> #DIV/0! | I33: =I$31/I$39/100 -> #DIV/0! | J33: =J$31/J$39/100 -> #DIV/0! | ... V33: =V$31/V$39/100 -> #DIV/0!
A35: Profitability
A36: Net Profit Margin (NPM) | C36: =C$16/ABS(C$13) -> 0.27583187 | D36: =D$16/ABS(D$13) -> 0.28822352 | E36: =E$16/ABS(E$13) -> 0.27396622 | F36: =F$16/ABS(F$13) -> 0.25173639 | G36: =G$16/ABS(G$13) -> 0.25735787 | H36: =H$16/ABS(H$13) -> 0.25267704 | I36: =I$16/ABS(I$13) -> 0.22396958 | J36: =J$16/ABS(J$13) -> 0.21856225 | ... V36: =V$16/ABS(V$13) -> 0.14918868
A38: Fair Price Scenario | B38: =B$2 -> Current | C38: =C$2 -> FY2025 | D38: =D$2 -> 9M2025 | E38: =E$2 -> 1H2025 | F38: =F$2 -> 1Q2025 | G38: =G$2 -> FY2024 | H38: =H$2 -> 9M2024 | I38: =I$2 -> 1H2024 | ... V38: =V$2 -> 1Q2021
A39: 5-Year EPS CAGR | C39: =(SUM(C$26:F$26)/SUM(S$26:V$26))^(1/5)-1 -> 0.33706695 | D39: =(SUM(D$26:G$26)/SUM(T$26:W$26))^(1/5)-1 -> 0.72637229 | E39: =(SUM(E$26:H$26)/SUM(U$26:X$26))^(1/5)-1 -> 0.75281139 | F39: =(SUM(F$26:I$26)/SUM(V$26:Y$26))^(1/5)-1 -> 0.65927865 | G39: =(SUM(G$26:J$26)/SUM(W$26:Z$26))^(1/5)-1 -> #DIV/0! | H39: =(SUM(H$26:K$26)/SUM(X$26:AA$26))^(1/5)-1 -> #DIV/0! | I39: =(SUM(I$26:L$26)/SUM(Y$26:AB$26))^(1/5)-1 -> #DIV/0! | J39: =(SUM(J$26:M$26)/SUM(Z$26:AC$26))^(1/5)-1 -> #DIV/0! | ... V39: =(SUM(V$26:Y$26)/SUM(AL$26:AO$26))^(1/5)-1 -> #DIV/0!
A41: Target PER (PEG 1.0x) | B41: =OFFSET($B41,0,1) -> 33.706695 | C41: =C$39*100 -> 33.706695 | D41: =D$39*100 -> 72.637229 | E41: =E$39*100 -> 75.281139 | F41: =F$39*100 -> 65.927865 | G41: =G$39*100 -> #DIV/0! | H41: =H$39*100 -> #DIV/0! | I41: =I$39*100 -> #DIV/0! | J41: =J$39*100 -> #DIV/0! | ... V41: =V$39*100 -> #DIV/0!
A42: Intrinsic Value | B42: =OFFSET($B42,0,1) -> 4755.0033 | C42: =C$41*SUM(C$26:F$26) -> 4755.0033 | D42: =D$41*SUM(D$26:G$26) -> 10166.448 | E42: =E$41*SUM(E$26:H$26) -> 10158.963 | F42: =F$41*SUM(F$26:I$26) -> 8157.9701 | G42: =G$41*SUM(G$26:J$26) -> #DIV/0! | H42: =H$41*SUM(H$26:K$26) -> #DIV/0! | I42: =I$41*SUM(I$26:L$26) -> #DIV/0! | J42: =J$41*SUM(J$26:M$26) -> #DIV/0! | ... V42: =V$41*SUM(V$26:Y$26) -> #DIV/0!
A43: Upside / (Downside) | B43: =(B$42-B$3)/ABS(B$3) -> 2.5618002 | C43: =(C$42-C$3)/ABS(C$3) -> 2.4332154 | D43: =(D$42-D$3)/ABS(D$3) -> 8.5459605 | E43: =(E$42-E$3)/ABS(E$3) -> 9.0583797 | F43: =(F$42-F$3)/ABS(F$3) -> 9.526413 | G43: =(G$42-G$3)/ABS(G$3) -> #DIV/0! | H43: =(H$42-H$3)/ABS(H$3) -> #DIV/0! | I43: =(I$42-I$3)/ABS(I$3) -> #DIV/0! | ... V43: =(V$42-V$3)/ABS(V$3) -> #DIV/0!

Sheet YTD - Quartely Report
A1: AAAA | B1: Integrated Freight & Logistics | C1: {=IF(C$7="Local Currency",1,_xlfn.XLOOKUP(C$2,OFFSET(Dashboard!$A:$A,0,MATCH(C$7,Dashboard!$1:$1,0)-1),OFFSET(Dashboard!$A:$A,0,MATCH(C$7,Dashboard!$1:$1,0))))} -> 1 | D1: {=IF(D$7="Local Currency",1,_xlfn.XLOOKUP(D$2,OFFSET(Dashboard!$A:$A,0,MATCH(D$7,Dashboard!$1:$1,0)-1),OFFSET(Dashboard!$A:$A,0,MATCH(D$7,Dashboard!$1:$1,0))))} -> 1 | E1: {=IF(E$7="Local Currency",1,_xlfn.XLOOKUP(E$2,OFFSET(Dashboard!$A:$A,0,MATCH(E$7,Dashboard!$1:$1,0)-1),OFFSET(Dashboard!$A:$A,0,MATCH(E$7,Dashboard!$1:$1,0))))} -> 1 | F1: {=IF(F$7="Local Currency",1,_xlfn.XLOOKUP(F$2,OFFSET(Dashboard!$A:$A,0,MATCH(F$7,Dashboard!$1:$1,0)-1),OFFSET(Dashboard!$A:$A,0,MATCH(F$7,Dashboard!$1:$1,0))))} -> 1 | G1: {=IF(G$7="Local Currency",1,_xlfn.XLOOKUP(G$2,OFFSET(Dashboard!$A:$A,0,MATCH(G$7,Dashboard!$1:$1,0)-1),OFFSET(Dashboard!$A:$A,0,MATCH(G$7,Dashboard!$1:$1,0))))} -> 1 | H1: {=IF(H$7="Local Currency",1,_xlfn.XLOOKUP(H$2,OFFSET(Dashboard!$A:$A,0,MATCH(H$7,Dashboard!$1:$1,0)-1),OFFSET(Dashboard!$A:$A,0,MATCH(H$7,Dashboard!$1:$1,0))))} -> 1 | I1: {=IF(I$7="Local Currency",1,_xlfn.XLOOKUP(I$2,OFFSET(Dashboard!$A:$A,0,MATCH(I$7,Dashboard!$1:$1,0)-1),OFFSET(Dashboard!$A:$A,0,MATCH(I$7,Dashboard!$1:$1,0))))} -> 1 | J1: {=IF(J$7="Local Currency",1,_xlfn.XLOOKUP(J$2,OFFSET(Dashboard!$A:$A,0,MATCH(J$7,Dashboard!$1:$1,0)-1),OFFSET(Dashboard!$A:$A,0,MATCH(J$7,Dashboard!$1:$1,0))))} -> 1 | ... V1: {=IF(V$7="Local Currency",1,_xlfn.XLOOKUP(V$2,OFFSET(Dashboard!$A:$A,0,MATCH(V$7,Dashboard!$1:$1,0)-1),OFFSET(Dashboard!$A:$A,0,MATCH(V$7,Dashboard!$1:$1,0))))} -> 1
A2: Market Data | B2: Current | C2: FY2025 | D2: 9M2025 | E2: 1H2025 | F2: 1Q2025 | G2: FY2024 | H2: 9M2024 | I2: 1H2024 | J2: 1Q2024 | K2: FY2023 | L2: 9M2023 | M2: 1H2023 | N2: 1Q2023 | O2: FY2022 | P2: 9M2022 | Q2: 1H2022 | R2: 1Q2022 | S2: FY2021 | T2: 9M2021 | U2: 1H2021 | V2: 1Q2021
A3: Price | B3: 1335 | C3: 1385 | D3: 1065 | E3: 1010 | F3: 775 | G3: 705 | H3: 685 | I3: 670 | J3: 690 | K3: 715 | L3: 710 | M3: 765 | N3: 625 | O3: 570 | P3: 505 | Q3: 615 | R3: 550 | S3: 515 | T3: 595 | U3: 490 | V3: 595
A5: Market Capitalization | B5: =B$3*OFFSET(B$5,0,1)/OFFSET(B$3,0,1) -> 2427178984665 | C5: =C$19*C$3 -> 2518084564615 | D5: =D$19*D$3 -> 1936684063785 | E5: =E$19*E$3 -> 1836493590860 | F5: =F$19*F$3 -> 1409291726950 | G5: =G$19*G$3 -> 1281580755315 | H5: =H$19*H$3 -> 1245773686145 | I5: =I$19*I$3 -> 1218278165400 | J5: =J$19*J$3 -> 1254740877600 | ... V5: =V$19*V$3 -> 1082036929295
A7: Currency | B7: {=IF(COUNTIF($C7:$7,INDEX($C7:$7,MATCH(TRUE,$C7:$7<>"",0)))=COUNTIF($C7:$7,"<>"),"All "&INDEX($C7:$7,MATCH(TRUE,$C7:$7<>"",0)),INDEX($C7:$7,MATCH(MAX(INDEX(COUNTIF($C7:$7,$C7:$7),0)),INDEX(COUNTIF($C7:$7,$C7:$7),0),0))&" Dominant")} -> All Local Currency | C7: Local Currency | D7: Local Currency | E7: Local Currency | F7: Local Currency | G7: Local Currency | H7: Local Currency | I7: Local Currency | J7: Local Currency | K7: Local Currency | L7: Local Currency | M7: Local Currency | N7: Local Currency | O7: Local Currency | P7: Local Currency | Q7: Local Currency | R7: Local Currency | S7: Local Currency | T7: Local Currency | U7: Local Currency | V7: Local Currency
A9: Consolidated Statements of Income | B9: =B$2 -> Current | C9: =C$2 -> FY2025 | D9: =D$2 -> 9M2025 | E9: =E$2 -> 1H2025 | F9: =F$2 -> 1Q2025 | G9: =G$2 -> FY2024 | H9: =H$2 -> 9M2024 | I9: =I$2 -> 1H2024 | ... V9: =V$2 -> 1Q2021
A10: Revenue | C10: 929960416000 | D10: 660240192000 | E10: 415550074000 | F10: 203271873000 | G10: 824595836000 | H10: 585823826000 | I10: 360261682000 | J10: 175637819000 | K10: 735204940000 | L10: 548162124000 | M10: 366960224000 | N10: 191151747000 | O10: 726573259000 | P10: 508339990000 | Q10: 302336582000 | R10: 150046126000 | S10: 516836950000 | T10: 347772241000 | U10: 233284768000 | V10: 119923887000
A11: Net Income | C11: 256512720000 | D11: 190296750000 | E11: 113846685000 | F11: 51170928000 | G11: 212216227000 | H11: 148024228000 | I11: 80687656000 | J11: 38387797000 | K11: 190854844000 | L11: 141942937000 | M11: 78917489000 | N11: 42333996000 | O11: 161724767000 | P11: 108895525000 | Q11: 45415809000 | R11: 35264224000 | S11: 60056174000 | T11: 16596355000 | U11: 14832433000 | V11: 17891287000
A13: Revenue (Quarterly) | C13: =IF(LEFT(C$2,2)="1Q",C$10,C$10-D$10) -> 269720224000 | D13: =IF(LEFT(D$2,2)="1Q",D$10,D$10-E$10) -> 244690118000 | E13: =IF(LEFT(E$2,2)="1Q",E$10,E$10-F$10) -> 212278201000 | F13: =IF(LEFT(F$2,2)="1Q",F$10,F$10-G$10) -> 203271873000 | G13: =IF(LEFT(G$2,2)="1Q",G$10,G$10-H$10) -> 238772010000 | H13: =IF(LEFT(H$2,2)="1Q",H$10,H$10-I$10) -> 225562144000 | I13: =IF(LEFT(I$2,2)="1Q",I$10,I$10-J$10) -> 184623863000 | J13: =IF(LEFT(J$2,2)="1Q",J$10,J$10-K$10) -> 175637819000 | ... V13: =IF(LEFT(V$2,2)="1Q",V$10,V$10-W$10) -> 119923887000
A14: Revenue Growth (YoY) | C14: =(C$10-G$10)/ABS(G$10) -> 0.12777724 | D14: =(D$10-H$10)/ABS(H$10) -> 0.12702858 | E14: =(E$10-I$10)/ABS(I$10) -> 0.15346731 | F14: =(F$10-J$10)/ABS(J$10) -> 0.15733544 | G14: =(G$10-K$10)/ABS(K$10) -> 0.12158636 | H14: =(H$10-L$10)/ABS(L$10) -> 0.068705407 | I14: =(I$10-M$10)/ABS(M$10) -> -0.018254136 | J14: =(J$10-N$10)/ABS(N$10) -> -0.081160273 | ... V14: =(V$10-Z$10)/ABS(Z$10) -> #DIV/0!
A16: Net Income (Quarterly) | C16: =IF(LEFT(C$2,2)="1Q",C$11,C$11-D$11) -> 66215970000 | D16: =IF(LEFT(D$2,2)="1Q",D$11,D$11-E$11) -> 76450065000 | E16: =IF(LEFT(E$2,2)="1Q",E$11,E$11-F$11) -> 62675757000 | F16: =IF(LEFT(F$2,2)="1Q",F$11,F$11-G$11) -> 51170928000 | G16: =IF(LEFT(G$2,2)="1Q",G$11,G$11-H$11) -> 64191999000 | H16: =IF(LEFT(H$2,2)="1Q",H$11,H$11-I$11) -> 67336572000 | I16: =IF(LEFT(I$2,2)="1Q",I$11,I$11-J$11) -> 42299859000 | J16: =IF(LEFT(J$2,2)="1Q",J$11,J$11-K$11) -> 38387797000 | ... V16: =IF(LEFT(V$2,2)="1Q",V$11,V$11-W$11) -> 17891287000
A17: Net Income Growth (YoY) | C17: =(C$11-G$11)/ABS(G$11) -> 0.20873283 | D17: =(D$11-H$11)/ABS(H$11) -> 0.2855784 | E17: =(E$11-I$11)/ABS(I$11) -> 0.41095541 | F17: =(F$11-J$11)/ABS(J$11) -> 0.33299986 | G17: =(G$11-K$11)/ABS(K$11) -> 0.11192476 | H17: =(H$11-L$11)/ABS(L$11) -> 0.04284321 | I17: =(I$11-M$11)/ABS(M$11) -> 0.022430605 | J17: =(J$11-N$11)/ABS(N$11) -> -0.09321584 | ... V17: =(V$11-Z$11)/ABS(Z$11) -> #DIV/0!
A19: Shares Outstanding | C19: 1818111599 | D19: 1818482689 | E19: 1818310486 | F19: 1818440938 | G19: 1817845043 | H19: 1818647717 | I19: 1818325620 | J19: 1818465040 | K19: 1818284091 | L19: 1818396817 | M19: 1818280026 | N19: 1818470618 | O19: 1818277789 | P19: 1818384807 | Q19: 1818088723 | R19: 1818680969 | S19: 1819576943 | T19: 1816577843 | U19: 1818549461 | V19: 1818549461
A21: Consolidated Balance Sheets | B21: =B$2 -> Current | C21: =C$2 -> FY2025 | D21: =D$2 -> 9M2025 | E21: =E$2 -> 1H2025 | F21: =F$2 -> 1Q2025 | G21: =G$2 -> FY2024 | H21: =H$2 -> 9M2024 | I21: =I$2 -> 1H2024 | ... V21: =V$2 -> 1Q2021
A22: Shareholders' Equity | C22: 1360801231000 | D22: 1342159480000 | E22: 1265709415000 | F22: 1328399319000 | G22: 1277228391000 | H22: 1257666157000 | I22: 1190106935000 | J22: 1261254651000 | K22: 1222866854000 | L22: 1213408389000 | M22: 1240883954000 | N22: 1204304183000 | O22: 1161970187000 | P22: 1131848849000 | Q22: 1110408454000 | R22: 1100256869000 | S22: 1064992645000 | T22: 1021532826000 | U22: 1019768905000 | V22: 1022827759000
A24: Ratio Analysis | B24: =B$2 -> Current | C24: =C$2 -> FY2025 | D24: =D$2 -> 9M2025 | E24: =E$2 -> 1H2025 | F24: =F$2 -> 1Q2025 | G24: =G$2 -> FY2024 | H24: =H$2 -> 9M2024 | I24: =I$2 -> 1H2024 | ... V24: =V$2 -> 1Q2021
A25: Earnings
A26: Earnings Per Share (EPS) (YTD) | C26: =C$11*C$1/C$19 -> 141.08744 | D26: =D$11*D$1/D$19 -> 104.6459 | E26: =E$11*E$1/E$19 -> 62.611246 | F26: =F$11*F$1/F$19 -> 28.14 | G26: =G$11*G$1/G$19 -> 116.74055 | H26: =H$11*H$1/H$19 -> 81.392469 | I26: =I$11*I$1/I$19 -> 44.374701 | J26: =J$11*J$1/J$19 -> 21.11 | ... V26: =V$11*V$1/V$19 -> 9.8382185
A27: Earnings Per Share (EPS) (Quarterly) | C27: =IF(LEFT(C$2,2)="1Q",C$26,C$26-D$26) -> 36.441549 | D27: =IF(LEFT(D$2,2)="1Q",D$26,D$26-E$26) -> 42.03465 | E27: =IF(LEFT(E$2,2)="1Q",E$26,E$26-F$26) -> 34.471246 | F27: =IF(LEFT(F$2,2)="1Q",F$26,F$26-G$26) -> 28.14 | G27: =IF(LEFT(G$2,2)="1Q",G$26,G$26-H$26) -> 35.348079 | H27: =IF(LEFT(H$2,2)="1Q",H$26,H$26-I$26) -> 37.017768 | I27: =IF(LEFT(I$2,2)="1Q",I$26,I$26-J$26) -> 23.264701 | J27: =IF(LEFT(J$2,2)="1Q",J$26,J$26-K$26) -> 21.11 | ... V27: =IF(LEFT(V$2,2)="1Q",V$26,V$26-W$26) -> 9.8382185
A28: Book Value Per Share (BVPS) | C28: =C$22*C$1/C$19 -> 748.46958 | D28: =D$22*D$1/D$19 -> 738.06558 | E28: =E$22*E$1/E$19 -> 696.09092 | F28: =F$22*F$1/F$19 -> 730.51552 | G28: =G$22*G$1/G$19 -> 702.60576 | H28: =H$22*H$1/H$19 -> 691.53918 | I28: =I$22*I$1/I$19 -> 654.50705 | J28: =J$22*J$1/J$19 -> 693.58202 | ... V28: =V$22*V$1/V$19 -> 562.44154
A30: Valuation
A31: Price Earnings Ratio (PER) (TTM) | B31: =$B$3/SUM(OFFSET($B$27,0,1,1,4)) -> 9.4622169 | C31: =C$3/SUM(C$27:F$27) -> 9.816607 | D31: =D$3/SUM(D$27:G$27) -> 7.6074702 | E31: =E$3/SUM(E$27:H$27) -> 7.4827512 | F31: =F$3/SUM(F$27:I$27) -> 6.2615865 | G31: =G$3/SUM(G$27:J$27) -> 6.0390328 | H31: =H$3/SUM(H$27:K$27) -> 6.3251782 | I31: =I$3/SUM(I$27:L$27) -> 6.3245323 | J31: =J$3/SUM(J$27:M$27) -> 6.7124371 | ... V31: =V$3/SUM(V$27:Y$27) -> 60.478429
A32: Price Book Value (PBV) | B32: =$B$3/OFFSET($B$28,0,1) -> 1.7836396 | C32: =C$3/C$28 -> 1.8504426 | D32: =D$3/D$28 -> 1.4429612 | E32: =E$3/E$28 -> 1.4509599 | F32: =F$3/F$28 -> 1.0608946 | G32: =G$3/G$28 -> 1.0034077 | H32: =H$3/H$28 -> 0.99054402 | I32: =I$3/I$28 -> 1.0236712 | J32: =J$3/J$28 -> 0.99483548 | ... V32: =V$3/V$28 -> 1.0578877
A33: Price Earnings Growth (PEG) | B33: =B$31/OFFSET($B39,0,1)/100 -> 0.28065278 | C33: =C$31/C$39/100 -> 0.29116412 | D33: =D$31/D$39/100 -> 0.10476927 | E33: =E$31/E$39/100 -> 0.0993871 | F33: =F$31/F$39/100 -> 0.094964856 | G33: =G$31/G$39/100 -> #DIV/0! | H33: =H$31/H$39/100 -> #DIV/0! | I33: =I$31/I$39/100 -> #DIV/0! | J33: =J$31/J$39/100 -> #DIV/0! | ... V33: =V$31/V$39/100 -> #DIV/0!
A35: Profitability
